Workbook

Sheet Guide
A1: Idle Cultivation: Balancing Model
A3: What this is
A4: A working model of the progression math from 03-Economy.md, 02-Systems.md (Vessel Model) and content/*.md. Change the inputs and every sheet recalculates.
A6: Color legend
A7: Blue text = input you can change · Black = formula · Green = pulled from another sheet · Yellow fill = key assumption
A9: Sheets
A10: Inputs: global constants, realm table (BASE, REALM_RATE, targets, rebirth gains, Karma), body-stage table.
A11: EXT_Budget: builds each realm's Qi multiplier (EXT) from grounds × Talisman × method × achievements × element match, and compares it with the old doc assumption.
A12: Qi_Pacing: level-by-level Vessel Model for all 10 Mortal realms (refill + growth time), cumulative meditation hours and calendar days.
A13: Body_Pacing: the same for the 7 body stages, using Train time.
A14: Rebirth: stacked Qi/Body gains, Karma, and a 6-life planner (edit the blue 'reached' cells) with Dao Marks if you ascend.
A15: Grounds_Economy: Spirit Stone income per tier vs Cultivation Ground upkeep, with recommended upkeep.
... A27: · SF–GA BASE values and Golden Body+ BODY_BASE values were tuned by this model to hit the registry targets; they are new numbers, not from the docs.

Sheet Inputs
A1: Inputs
A3: Global constants | B3: Value | C3: Note / source
A4: Cost growth per level (G) | B4: 1.15 | C4: 03-Economy: work × 1.15 per level
A5: Rate growth per level (P) | B5: 1.1 | C5: 03-Economy: rate × 1.10 per level
A6: Expansion efficiency | B6: 0.25 | C6: Vessel Model: 4 points → +1 max while full
A7: Level spend (% of cap) | B7: 0.8 | C7: Breakthrough spends 80% of cap (gates 100%)
A8: Cap factor (cap = factor × work) | B8: 0.76 | C8: 03-Economy cap(R,L) = 0.76 × work
A9: Peak cap multiplier (level 9) | B9: 1.6 | C9: cap(R,9) = 1.6 × cap(R,8)
A10: Effective hours per day | B10: 12 | C10: Online + offline within the 8 h cap, 3–6 check-ins
A11: Meditate share | B11: 0.4 | C11: Activity split assumption (03-Economy)
A12: Train share | B12: 0.3 | C12: Activity split assumption
A13: Battle share | B13: =1-B11-B12 | C13: Remainder
A14: Base regen (% of full rate) | B14: 0.1 | C14: Always on; refills only, never grows max
A15: Offline combat efficiency | B15: 0.8 | C15: Decision #8
A16: Body stage rate step | B16: 4 | C16: Tempering rate × 4 per body stage
A17: Achievement Qi bonus at 100% | B17: 3 | C17: Decision #62: +300% total
A18: Stone income growth per tier (T5+) | B18: 7 | C18: 03-Economy: ×7 per tier from SF
A19: Target upkeep share of income | B19: 0.12 | C19: 15-Cultivation-Grounds: about 10–15%
A21: Mortal Plane realms
A22: Idx | B22: Realm | C22: Abbrev | D22: Tier | E22: BASE (L1 work) | F22: REALM_RATE | G22: Target reach day | H22: REALM_GAIN | I22: Qi Karma add | J22: EXT override (blank = use EXT_Budget)
A23: 1 | B23: Meridian Opening | C23: MO | D23: T1 | E23: 15 | F23: 0.6 | G23: 0 | H23: 0 | I23: 0
A24: 2 | B24: Qi Condensation | C24: QC | D24: T1 | E24: 50 | F24: 1 | G24: 0.02 | H24: 0 | I24: 0
A25: 3 | B25: Qi Sea | C25: QS | D25: T1 | E25: 250 | F25: 2 | G25: 0.06 | H25: 0 | I25: 0
A26: 4 | B26: Foundation Establishment | C26: FE | D26: T2 | E26: 12000 | F26: 5 | G26: 0.2 | H26: 0 | I26: 0
A27: 5 | B27: Golden Core | C27: GC | D27: T3 | E27: 400000 | F27: 25 | G27: 1 | H27: 0.5 | I27: 2
A28: 6 | B28: Nascent Soul | C28: NS | D28: T4 | E28: 13000000 | F28: 125 | G28: 5 | H28: 1 | I28: 3
A29: 7 | B29: Soul Formation | C29: SF | D29: T5 | E29: 130000000 | F29: 625 | G29: 21 | H29: 2 | I29: 4
A30: 8 | B30: Void Breaking | C30: VB | D30: T6 | E30: 1600000000 | F30: 3125 | G30: 40 | H30: 4 | I30: 5
A31: 9 | B31: Mahayana | C31: MA | D31: T7 | E31: 27000000000 | F31: 15625 | G31: 65 | H31: 8 | I31: 6
A32: 10 | B32: Great Ascension | C32: GA | D32: T8–T9 | E32: 460000000000 | F32: 78125 | G32: 110 | H32: 16 | I32: 7
B33: Ascension (GA complete) | C33: ASC | G33: 180
A34: Target days: content/00-Registry.md (first life, 40/30/30 split). REALM_GAIN and Karma: 03-Economy / content/12-Rebirth.
A36: Body stages
A37: Idx | B37: Stage | C37: BODY_BASE (L1 work) | D37: EXT_body | E37: Target completion day | F37: STAGE_GAIN | G37: Body Karma add
A38: 1 | B38: Copper Skin | C38: 400 | D38: 1 | E38: 0.4 | F38: 0 | G38: 0
A39: 2 | B39: Iron Bone | C39: 12500 | D39: 1.5 | E39: 2.5 | F39: 0.5 | G39: 1
A40: 3 | B40: Silver Marrow | C40: 300000 | D40: 2.5 | E40: 11 | F40: 1 | G40: 2
A41: 4 | B41: Jade Flesh | C41: 4700000 | D41: 4 | E41: 30 | F41: 2 | G41: 3
A42: 5 | B42: Golden Body | C42: 77000000 | D42: 6 | E42: 72 | F42: 4 | G42: 4
A43: 6 | B43: Diamond Vajra Body | C43: 840000000 | D43: 9 | E43: 155 | F43: 8 | G43: 5
...

Sheet EXT_Budget
A1: EXT budget: what actually multiplies Qi rate in each realm
A3: Realm | B3: Best Meditation ground × | C3: Typical Talisman Qi × | D3: Cultivation method × | E3: Achievements earned (share of total) | F3: Element match × | G3: Achievement × | H3: Computed EXT | I3: Old doc EXT | J3: Computed ÷ doc | K3: EXT used in pacing
A4: =Inputs!C23 | B4: 1 | C4: 1 | D4: 1 | E4: 0 | F4: 1 | G4: =1+E4*Inputs!$B$17 | H4: =B4*C4*D4*G4*F4 | I4: 1 | J4: =IF(I4="","",H4/I4) | K4: =IF(Inputs!J23="",H4,Inputs!J23)
A5: =Inputs!C24 | B5: 1.1 | C5: 1.05 | D5: 1 | E5: 0 | F5: 1 | G5: =1+E5*Inputs!$B$17 | H5: =B5*C5*D5*G5*F5 | I5: 1 | J5: =IF(I5="","",H5/I5) | K5: =IF(Inputs!J24="",H5,Inputs!J24)
A6: =Inputs!C25 | B6: 1.1 | C6: 1.06 | D6: 1 | E6: 0.003 | F6: 1 | G6: =1+E6*Inputs!$B$17 | H6: =B6*C6*D6*G6*F6 | I6: 1 | J6: =IF(I6="","",H6/I6) | K6: =IF(Inputs!J25="",H6,Inputs!J25)
A7: =Inputs!C26 | B7: 1.25 | C7: 1.17 | D7: 1.2 | E7: 0.01 | F7: 1.1 | G7: =1+E7*Inputs!$B$17 | H7: =B7*C7*D7*G7*F7 | I7: 1.5 | J7: =IF(I7="","",H7/I7) | K7: =IF(Inputs!J26="",H7,Inputs!J26)
A8: =Inputs!C27 | B8: 1.4 | C8: 1.31 | D8: 1.35 | E8: 0.02 | F8: 1.1 | G8: =1+E8*Inputs!$B$17 | H8: =B8*C8*D8*G8*F8 | I8: 2.5 | J8: =IF(I8="","",H8/I8) | K8: =IF(Inputs!J27="",H8,Inputs!J27)
A9: =Inputs!C28 | B9: 1.65 | C9: 1.4 | D9: 1.5 | E9: 0.04 | F9: 1.1 | G9: =1+E9*Inputs!$B$17 | H9: =B9*C9*D9*G9*F9 | I9: 4 | J9: =IF(I9="","",H9/I9) | K9: =IF(Inputs!J28="",H9,Inputs!J28)
A10: =Inputs!C29 | B10: 2.05 | C10: 1.57 | D10: 1.7 | E10: 0.1 | F10: 1.1 | G10: =1+E10*Inputs!$B$17 | H10: =B10*C10*D10*G10*F10 | J10: =IF(I10="","",H10/I10) | K10: =IF(Inputs!J29="",H10,Inputs!J29)
A11: =Inputs!C30 | B11: 2.3 | C11: 1.7 | D11: 2 | E11: 0.2 | F11: 1.1 | G11: =1+E11*Inputs!$B$17 | H11: =B11*C11*D11*G11*F11 | J11: =IF(I11="","",H11/I11) | K11: =IF(Inputs!J30="",H11,Inputs!J30)
A12: =Inputs!C31 | B12: 2.85 | C12: 1.85 | D12: 2.3 | E12: 0.33 | F12: 1.1 | G12: =1+E12*Inputs!$B$17 | H12: =B12*C12*D12*G12*F12 | J12: =IF(I12="","",H12/I12) | K12: =IF(Inputs!J31="",H12,Inputs!J31)
A13: =Inputs!C32 | B13: 3.6 | C13: 2 | D13: 2.6 | E13: 0.6 | F13: 1.1 | G13: =1+E13*Inputs!$B$17 | H13: =B13*C13*D13*G13*F13 | J13: =IF(I13="","",H13/I13) | K13: =IF(Inputs!J32="",H13,Inputs!J32)
A15: Sources: grounds from content/15-Cultivation-Grounds (best site usable mid-realm); Talisman = typical rarity for the realm from 02-Systems §4 accessory ranges; method = 06-Techniques progression (assumed); achievements = assumed share of the +300% total earned by that realm; element match +10% from FE.

Sheet Qi_Pacing
A1: Qi pacing (Vessel Model, Meditate time)
A3: Key | B3: Idx | C3: Level | D3: Rate /s | E3: Work | F3: Cap (max at level end) | G3: Start max | H3: Refill amount | I3: Refill h | J3: Growth h | K3: Level h | L3: Cumulative h | M3: Day (end of level) | N3: Day (level reached)
A4: =Inputs!$C$23&" 1" | B4: 1 | C4: 1 | D4: =INDEX(Inputs!$F$23:$F$32,B4)*Inputs!$B$5^(C4-1)*INDEX(EXT_Budget!$K$4:$K$13,B4) | E4: =INDEX(Inputs!$E$23:$E$32,B4)*Inputs!$B$4^(C4-1) | F4: =IF(C4<9,Inputs!$B$8*E4,Inputs!$B$9*Inputs!$B$8*INDEX(Inputs!$E$23:$E$32,B4)*Inputs!$B$4^7) | G4: =F4/Inputs!$B$4 | H4: =G4 | I4: =H4/D4/3600 | J4: =(F4-G4)/(Inputs!$B$6*D4)/3600 | K4: =I4+J4 | L4: =K4 | M4: =L4/(Inputs!$B$10*Inputs!$B$11) | N4: =(L4-K4)/(Inputs!$B$10*Inputs!$B$11)
A5: =Inputs!$C$23&" 2" | B5: 1 | C5: 2 | D5: =INDEX(Inputs!$F$23:$F$32,B5)*Inputs!$B$5^(C5-1)*INDEX(EXT_Budget!$K$4:$K$13,B5) | E5: =INDEX(Inputs!$E$23:$E$32,B5)*Inputs!$B$4^(C5-1) | F5: =IF(C5<9,Inputs!$B$8*E5,Inputs!$B$9*Inputs!$B$8*INDEX(Inputs!$E$23:$E$32,B5)*Inputs!$B$4^7) | G5: =IF(C5=1,F5/Inputs!$B$4,F4) | H5: =IF(C5=1,G5,Inputs!$B$7*F4) | I5: =H5/D5/3600 | J5: =(F5-G5)/(Inputs!$B$6*D5)/3600 | K5: =I5+J5 | L5: =L4+K5 | M5: =L5/(Inputs!$B$10*Inputs!$B$11) | N5: =(L5-K5)/(Inputs!$B$10*Inputs!$B$11)
A6: =Inputs!$C$23&" 3" | B6: 1 | C6: 3 | D6: =INDEX(Inputs!$F$23:$F$32,B6)*Inputs!$B$5^(C6-1)*INDEX(EXT_Budget!$K$4:$K$13,B6) | E6: =INDEX(Inputs!$E$23:$E$32,B6)*Inputs!$B$4^(C6-1) | F6: =IF(C6<9,Inputs!$B$8*E6,Inputs!$B$9*Inputs!$B$8*INDEX(Inputs!$E$23:$E$32,B6)*Inputs!$B$4^7) | G6: =IF(C6=1,F6/Inputs!$B$4,F5) | H6: =IF(C6=1,G6,Inputs!$B$7*F5) | I6: =H6/D6/3600 | J6: =(F6-G6)/(Inputs!$B$6*D6)/3600 | K6: =I6+J6 | L6: =L5+K6 | M6: =L6/(Inputs!$B$10*Inputs!$B$11) | N6: =(L6-K6)/(Inputs!$B$10*Inputs!$B$11)
A7: =Inputs!$C$23&" 4" | B7: 1 | C7: 4 | D7: =INDEX(Inputs!$F$23:$F$32,B7)*Inputs!$B$5^(C7-1)*INDEX(EXT_Budget!$K$4:$K$13,B7) | E7: =INDEX(Inputs!$E$23:$E$32,B7)*Inputs!$B$4^(C7-1) | F7: =IF(C7<9,Inputs!$B$8*E7,Inputs!$B$9*Inputs!$B$8*INDEX(Inputs!$E$23:$E$32,B7)*Inputs!$B$4^7) | G7: =IF(C7=1,F7/Inputs!$B$4,F6) | H7: =IF(C7=1,G7,Inputs!$B$7*F6) | I7: =H7/D7/3600 | J7: =(F7-G7)/(Inputs!$B$6*D7)/3600 | K7: =I7+J7 | L7: =L6+K7 | M7: =L7/(Inputs!$B$10*Inputs!$B$11) | N7: =(L7-K7)/(Inputs!$B$10*Inputs!$B$11)
A8: =Inputs!$C$23&" 5" | B8: 1 | C8: 5 | D8: =INDEX(Inputs!$F$23:$F$32,B8)*Inputs!$B$5^(C8-1)*INDEX(EXT_Budget!$K$4:$K$13,B8) | E8: =INDEX(Inputs!$E$23:$E$32,B8)*Inputs!$B$4^(C8-1) | F8: =IF(C8<9,Inputs!$B$8*E8,Inputs!$B$9*Inputs!$B$8*INDEX(Inputs!$E$23:$E$32,B8)*Inputs!$B$4^7) | G8: =IF(C8=1,F8/Inputs!$B$4,F7) | H8: =IF(C8=1,G8,Inputs!$B$7*F7) | I8: =H8/D8/3600 | J8: =(F8-G8)/(Inputs!$B$6*D8)/3600 | K8: =I8+J8 | L8: =L7+K8 | M8: =L8/(Inputs!$B$10*Inputs!$B$11) | N8: =(L8-K8)/(Inputs!$B$10*Inputs!$B$11)
A9: =Inputs!$C$23&" 6" | B9: 1 | C9: 6 | D9: =INDEX(Inputs!$F$23:$F$32,B9)*Inputs!$B$5^(C9-1)*INDEX(EXT_Budget!$K$4:$K$13,B9) | E9: =INDEX(Inputs!$E$23:$E$32,B9)*Inputs!$B$4^(C9-1) | F9: =IF(C9<9,Inputs!$B$8*E9,Inputs!$B$9*Inputs!$B$8*INDEX(Inputs!$E$23:$E$32,B9)*Inputs!$B$4^7) | G9: =IF(C9=1,F9/Inputs!$B$4,F8) | H9: =IF(C9=1,G9,Inputs!$B$7*F8) | I9: =H9/D9/3600 | J9: =(F9-G9)/(Inputs!$B$6*D9)/3600 | K9: =I9+J9 | L9: =L8+K9 | M9: =L9/(Inputs!$B$10*Inputs!$B$11) | N9: =(L9-K9)/(Inputs!$B$10*Inputs!$B$11)
A10: =Inputs!$C$23&" 7" | B10: 1 | C10: 7 | D10: =INDEX(Inputs!$F$23:$F$32,B10)*Inputs!$B$5^(C10-1)*INDEX(EXT_Budget!$K$4:$K$13,B10) | E10: =INDEX(Inputs!$E$23:$E$32,B10)*Inputs!$B$4^(C10-1) | F10: =IF(C10<9,Inputs!$B$8*E10,Inputs!$B$9*Inputs!$B$8*INDEX(Inputs!$E$23:$E$32,B10)*Inputs!$B$4^7) | G10: =IF(C10=1,F10/Inputs!$B$4,F9) | H10: =IF(C10=1,G10,Inputs!$B$7*F9) | I10: =H10/D10/3600 | J10: =(F10-G10)/(Inputs!$B$6*D10)/3600 | K10: =I10+J10 | L10: =L9+K10 | M10: =L10/(Inputs!$B$10*Inputs!$B$11) | N10: =(L10-K10)/(Inputs!$B$10*Inputs!$B$11)
A11: =Inputs!$C$23&" 8" | B11: 1 | C11: 8 | D11: =INDEX(Inputs!$F$23:$F$32,B11)*Inputs!$B$5^(C11-1)*INDEX(EXT_Budget!$K$4:$K$13,B11) | E11: =INDEX(Inputs!$E$23:$E$32,B11)*Inputs!$B$4^(C11-1) | F11: =IF(C11<9,Inputs!$B$8*E11,Inputs!$B$9*Inputs!$B$8*INDEX(Inputs!$E$23:$E$32,B11)*Inputs!$B$4^7) | G11: =IF(C11=1,F11/Inputs!$B$4,F10) | H11: =IF(C11=1,G11,Inputs!$B$7*F10) | I11: =H11/D11/3600 | J11: =(F11-G11)/(Inputs!$B$6*D11)/3600 | K11: =I11+J11 | L11: =L10+K11 | M11: =L11/(Inputs!$B$10*Inputs!$B$11) | N11: =(L11-K11)/(Inputs!$B$10*Inputs!$B$11)
A12: =Inputs!$C$23&" 9" | B12: 1 | C12: 9 | D12: =INDEX(Inputs!$F$23:$F$32,B12)*Inputs!$B$5^(C12-1)*INDEX(EXT_Budget!$K$4:$K$13,B12) | E12: =INDEX(Inputs!$E$23:$E$32,B12)*Inputs!$B$4^(C12-1) | F12: =IF(C12<9,Inputs!$B$8*E12,Inputs!$B$9*Inputs!$B$8*INDEX(Inputs!$E$23:$E$32,B12)*Inputs!$B$4^7) | G12: =IF(C12=1,F12/Inputs!$B$4,F11) | H12: =IF(C12=1,G12,Inputs!$B$7*F11) | I12: =H12/D12/3600 | J12: =(F12-G12)/(Inputs!$B$6*D12)/3600 | K12: =I12+J12 | L12: =L11+K12 | M12: =L12/(Inputs!$B$10*Inputs!$B$11) | N12: =(L12-K12)/(Inputs!$B$10*Inputs!$B$11)
A13: =Inputs!$C$24&" 1" | B13: 2 | C13: 1 | D13: =INDEX(Inputs!$F$23:$F$32,B13)*Inputs!$B$5^(C13-1)*INDEX(EXT_Budget!$K$4:$K$13,B13) | E13: =INDEX(Inputs!$E$23:$E$32,B13)*Inputs!$B$4^(C13-1) | F13: =IF(C13<9,Inputs!$B$8*E13,Inputs!$B$9*Inputs!$B$8*INDEX(Inputs!$E$23:$E$32,B13)*Inputs!$B$4^7) | G13: =IF(C13=1,F13/Inputs!$B$4,F12) | H13: =IF(C13=1,G13,Inputs!$B$7*F12) | I13: =H13/D13/3600 | J13: =(F13-G13)/(Inputs!$B$6*D13)/3600 | K13: =I13+J13 | L13: =L12+K13 | M13: =L13/(Inputs!$B$10*Inputs!$B$11) | N13: =(L13-K13)/(Inputs!$B$10*Inputs!$B$11)
A14: =Inputs!$C$24&" 2" | B14: 2 | C14: 2 | D14: =INDEX(Inputs!$F$23:$F$32,B14)*Inputs!$B$5^(C14-1)*INDEX(EXT_Budget!$K$4:$K$13,B14) | E14: =INDEX(Inputs!$E$23:$E$32,B14)*Inputs!$B$4^(C14-1) | F14: =IF(C14<9,Inputs!$B$8*E14,Inputs!$B$9*Inputs!$B$8*INDEX(Inputs!$E$23:$E$32,B14)*Inputs!$B$4^7) | G14: =IF(C14=1,F14/Inputs!$B$4,F13) | H14: =IF(C14=1,G14,Inputs!$B$7*F13) | I14: =H14/D14/3600 | J14: =(F14-G14)/(Inputs!$B$6*D14)/3600 | K14: =I14+J14 | L14: =L13+K14 | M14: =L14/(Inputs!$B$10*Inputs!$B$11) | N14: =(L14-K14)/(Inputs!$B$10*Inputs!$B$11)
A15: =Inputs!$C$24&" 3" | B15: 2 | C15: 3 | D15: =INDEX(Inputs!$F$23:$F$32,B15)*Inputs!$B$5^(C15-1)*INDEX(EXT_Budget!$K$4:$K$13,B15) | E15: =INDEX(Inputs!$E$23:$E$32,B15)*Inputs!$B$4^(C15-1) | F15: =IF(C15<9,Inputs!$B$8*E15,Inputs!$B$9*Inputs!$B$8*INDEX(Inputs!$E$23:$E$32,B15)*Inputs!$B$4^7) | G15: =IF(C15=1,F15/Inputs!$B$4,F14) | H15: =IF(C15=1,G15,Inputs!$B$7*F14) | I15: =H15/D15/3600 | J15: =(F15-G15)/(Inputs!$B$6*D15)/3600 | K15: =I15+J15 | L15: =L14+K15 | M15: =L15/(Inputs!$B$10*Inputs!$B$11) | N15: =(L15-K15)/(Inputs!$B$10*Inputs!$B$11)
A16: =Inputs!$C$24&" 4" | B16: 2 | C16: 4 | D16: =INDEX(Inputs!$F$23:$F$32,B16)*Inputs!$B$5^(C16-1)*INDEX(EXT_Budget!$K$4:$K$13,B16) | E16: =INDEX(Inputs!$E$23:$E$32,B16)*Inputs!$B$4^(C16-1) | F16: =IF(C16<9,Inputs!$B$8*E16,Inputs!$B$9*Inputs!$B$8*INDEX(Inputs!$E$23:$E$32,B16)*Inputs!$B$4^7) | G16: =IF(C16=1,F16/Inputs!$B$4,F15) | H16: =IF(C16=1,G16,Inputs!$B$7*F15) | I16: =H16/D16/3600 | J16: =(F16-G16)/(Inputs!$B$6*D16)/3600 | K16: =I16+J16 | L16: =L15+K16 | M16: =L16/(Inputs!$B$10*Inputs!$B$11) | N16: =(L16-K16)/(Inputs!$B$10*Inputs!$B$11)
A17: =Inputs!$C$24&" 5" | B17: 2 | C17: 5 | D17: =INDEX(Inputs!$F$23:$F$32,B17)*Inputs!$B$5^(C17-1)*INDEX(EXT_Budget!$K$4:$K$13,B17) | E17: =INDEX(Inputs!$E$23:$E$32,B17)*Inputs!$B$4^(C17-1) | F17: =IF(C17<9,Inputs!$B$8*E17,Inputs!$B$9*Inputs!$B$8*INDEX(Inputs!$E$23:$E$32,B17)*Inputs!$B$4^7) | G17: =IF(C17=1,F17/Inputs!$B$4,F16) | H17: =IF(C17=1,G17,Inputs!$B$7*F16) | I17: =H17/D17/3600 | J17: =(F17-G17)/(Inputs!$B$6*D17)/3600 | K17: =I17+J17 | L17: =L16+K17 | M17: =L17/(Inputs!$B$10*Inputs!$B$11) | N17: =(L17-K17)/(Inputs!$B$10*Inputs!$B$11)
A18: =Inputs!$C$24&" 6" | B18: 2 | C18: 6 | D18: =INDEX(Inputs!$F$23:$F$32,B18)*Inputs!$B$5^(C18-1)*INDEX(EXT_Budget!$K$4:$K$13,B18) | E18: =INDEX(Inputs!$E$23:$E$32,B18)*Inputs!$B$4^(C18-1) | F18: =IF(C18<9,Inputs!$B$8*E18,Inputs!$B$9*Inputs!$B$8*INDEX(Inputs!$E$23:$E$32,B18)*Inputs!$B$4^7) | G18: =IF(C18=1,F18/Inputs!$B$4,F17) | H18: =IF(C18=1,G18,Inputs!$B$7*F17) | I18: =H18/D18/3600 | J18: =(F18-G18)/(Inputs!$B$6*D18)/3600 | K18: =I18+J18 | L18: =L17+K18 | M18: =L18/(Inputs!$B$10*Inputs!$B$11) | N18: =(L18-K18)/(Inputs!$B$10*Inputs!$B$11)
A19: =Inputs!$C$24&" 7" | B19: 2 | C19: 7 | D19: =INDEX(Inputs!$F$23:$F$32,B19)*Inputs!$B$5^(C19-1)*INDEX(EXT_Budget!$K$4:$K$13,B19) | E19: =INDEX(Inputs!$E$23:$E$32,B19)*Inputs!$B$4^(C19-1) | F19: =IF(C19<9,Inputs!$B$8*E19,Inputs!$B$9*Inputs!$B$8*INDEX(Inputs!$E$23:$E$32,B19)*Inputs!$B$4^7) | G19: =IF(C19=1,F19/Inputs!$B$4,F18) | H19: =IF(C19=1,G19,Inputs!$B$7*F18) | I19: =H19/D19/3600 | J19: =(F19-G19)/(Inputs!$B$6*D19)/3600 | K19: =I19+J19 | L19: =L18+K19 | M19: =L19/(Inputs!$B$10*Inputs!$B$11) | N19: =(L19-K19)/(Inputs!$B$10*Inputs!$B$11)
A20: =Inputs!$C$24&" 8" | B20: 2 | C20: 8 | D20: =INDEX(Inputs!$F$23:$F$32,B20)*Inputs!$B$5^(C20-1)*INDEX(EXT_Budget!$K$4:$K$13,B20) | E20: =INDEX(Inputs!$E$23:$E$32,B20)*Inputs!$B$4^(C20-1) | F20: =IF(C20<9,Inputs!$B$8*E20,Inputs!$B$9*Inputs!$B$8*INDEX(Inputs!$E$23:$E$32,B20)*Inputs!$B$4^7) | G20: =IF(C20=1,F20/Inputs!$B$4,F19) | H20: =IF(C20=1,G20,Inputs!$B$7*F19) | I20: =H20/D20/3600 | J20: =(F20-G20)/(Inputs!$B$6*D20)/3600 | K20: =I20+J20 | L20: =L19+K20 | M20: =L20/(Inputs!$B$10*Inputs!$B$11) | N20: =(L20-K20)/(Inputs!$B$10*Inputs!$B$11)
A21: =Inputs!$C$24&" 9" | B21: 2 | C21: 9 | D21: =INDEX(Inputs!$F$23:$F$32,B21)*Inputs!$B$5^(C21-1)*INDEX(EXT_Budget!$K$4:$K$13,B21) | E21: =INDEX(Inputs!$E$23:$E$32,B21)*Inputs!$B$4^(C21-1) | F21: =IF(C21<9,Inputs!$B$8*E21,Inputs!$B$9*Inputs!$B$8*INDEX(Inputs!$E$23:$E$32,B21)*Inputs!$B$4^7) | G21: =IF(C21=1,F21/Inputs!$B$4,F20) | H21: =IF(C21=1,G21,Inputs!$B$7*F20) | I21: =H21/D21/3600 | J21: =(F21-G21)/(Inputs!$B$6*D21)/3600 | K21: =I21+J21 | L21: =L20+K21 | M21: =L21/(Inputs!$B$10*Inputs!$B$11) | N21: =(L21-K21)/(Inputs!$B$10*Inputs!$B$11)
A22: =Inputs!$C$25&" 1" | B22: 3 | C22: 1 | D22: =INDEX(Inputs!$F$23:$F$32,B22)*Inputs!$B$5^(C22-1)*INDEX(EXT_Budget!$K$4:$K$13,B22) | E22: =INDEX(Inputs!$E$23:$E$32,B22)*Inputs!$B$4^(C22-1) | F22: =IF(C22<9,Inputs!$B$8*E22,Inputs!$B$9*Inputs!$B$8*INDEX(Inputs!$E$23:$E$32,B22)*Inputs!$B$4^7) | G22: =IF(C22=1,F22/Inputs!$B$4,F21) | H22: =IF(C22=1,G22,Inputs!$B$7*F21) | I22: =H22/D22/3600 | J22: =(F22-G22)/(Inputs!$B$6*D22)/3600 | K22: =I22+J22 | L22: =L21+K22 | M22: =L22/(Inputs!$B$10*Inputs!$B$11) | N22: =(L22-K22)/(Inputs!$B$10*Inputs!$B$11)
A23: =Inputs!$C$25&" 2" | B23: 3 | C23: 2 | D23: =INDEX(Inputs!$F$23:$F$32,B23)*Inputs!$B$5^(C23-1)*INDEX(EXT_Budget!$K$4:$K$13,B23) | E23: =INDEX(Inputs!$E$23:$E$32,B23)*Inputs!$B$4^(C23-1) | F23: =IF(C23<9,Inputs!$B$8*E23,Inputs!$B$9*Inputs!$B$8*INDEX(Inputs!$E$23:$E$32,B23)*Inputs!$B$4^7) | G23: =IF(C23=1,F23/Inputs!$B$4,F22) | H23: =IF(C23=1,G23,Inputs!$B$7*F22) | I23: =H23/D23/3600 | J23: =(F23-G23)/(Inputs!$B$6*D23)/3600 | K23: =I23+J23 | L23: =L22+K23 | M23: =L23/(Inputs!$B$10*Inputs!$B$11) | N23: =(L23-K23)/(Inputs!$B$10*Inputs!$B$11)
A24: =Inputs!$C$25&" 3" | B24: 3 | C24: 3 | D24: =INDEX(Inputs!$F$23:$F$32,B24)*Inputs!$B$5^(C24-1)*INDEX(EXT_Budget!$K$4:$K$13,B24) | E24: =INDEX(Inputs!$E$23:$E$32,B24)*Inputs!$B$4^(C24-1) | F24: =IF(C24<9,Inputs!$B$8*E24,Inputs!$B$9*Inputs!$B$8*INDEX(Inputs!$E$23:$E$32,B24)*Inputs!$B$4^7) | G24: =IF(C24=1,F24/Inputs!$B$4,F23) | H24: =IF(C24=1,G24,Inputs!$B$7*F23) | I24: =H24/D24/3600 | J24: =(F24-G24)/(Inputs!$B$6*D24)/3600 | K24: =I24+J24 | L24: =L23+K24 | M24: =L24/(Inputs!$B$10*Inputs!$B$11) | N24: =(L24-K24)/(Inputs!$B$10*Inputs!$B$11)
A25: =Inputs!$C$25&" 4" | B25: 3 | C25: 4 | D25: =INDEX(Inputs!$F$23:$F$32,B25)*Inputs!$B$5^(C25-1)*INDEX(EXT_Budget!$K$4:$K$13,B25) | E25: =INDEX(Inputs!$E$23:$E$32,B25)*Inputs!$B$4^(C25-1) | F25: =IF(C25<9,Inputs!$B$8*E25,Inputs!$B$9*Inputs!$B$8*INDEX(Inputs!$E$23:$E$32,B25)*Inputs!$B$4^7) | G25: =IF(C25=1,F25/Inputs!$B$4,F24) | H25: =IF(C25=1,G25,Inputs!$B$7*F24) | I25: =H25/D25/3600 | J25: =(F25-G25)/(Inputs!$B$6*D25)/3600 | K25: =I25+J25 | L25: =L24+K25 | M25: =L25/(Inputs!$B$10*Inputs!$B$11) | N25: =(L25-K25)/(Inputs!$B$10*Inputs!$B$11)
A26: =Inputs!$C$25&" 5" | B26: 3 | C26: 5 | D26: =INDEX(Inputs!$F$23:$F$32,B26)*Inputs!$B$5^(C26-1)*INDEX(EXT_Budget!$K$4:$K$13,B26) | E26: =INDEX(Inputs!$E$23:$E$32,B26)*Inputs!$B$4^(C26-1) | F26: =IF(C26<9,Inputs!$B$8*E26,Inputs!$B$9*Inputs!$B$8*INDEX(Inputs!$E$23:$E$32,B26)*Inputs!$B$4^7) | G26: =IF(C26=1,F26/Inputs!$B$4,F25) | H26: =IF(C26=1,G26,Inputs!$B$7*F25) | I26: =H26/D26/3600 | J26: =(F26-G26)/(Inputs!$B$6*D26)/3600 | K26: =I26+J26 | L26: =L25+K26 | M26: =L26/(Inputs!$B$10*Inputs!$B$11) | N26: =(L26-K26)/(Inputs!$B$10*Inputs!$B$11)
A27: =Inputs!$C$25&" 6" | B27: 3 | C27: 6 | D27: =INDEX(Inputs!$F$23:$F$32,B27)*Inputs!$B$5^(C27-1)*INDEX(EXT_Budget!$K$4:$K$13,B27) | E27: =INDEX(Inputs!$E$23:$E$32,B27)*Inputs!$B$4^(C27-1) | F27: =IF(C27<9,Inputs!$B$8*E27,Inputs!$B$9*Inputs!$B$8*INDEX(Inputs!$E$23:$E$32,B27)*Inputs!$B$4^7) | G27: =IF(C27=1,F27/Inputs!$B$4,F26) | H27: =IF(C27=1,G27,Inputs!$B$7*F26) | I27: =H27/D27/3600 | J27: =(F27-G27)/(Inputs!$B$6*D27)/3600 | K27: =I27+J27 | L27: =L26+K27 | M27: =L27/(Inputs!$B$10*Inputs!$B$11) | N27: =(L27-K27)/(Inputs!$B$10*Inputs!$B$11)
A28: =Inputs!$C$25&" 7" | B28: 3 | C28: 7 | D28: =INDEX(Inputs!$F$23:$F$32,B28)*Inputs!$B$5^(C28-1)*INDEX(EXT_Budget!$K$4:$K$13,B28) | E28: =INDEX(Inputs!$E$23:$E$32,B28)*Inputs!$B$4^(C28-1) | F28: =IF(C28<9,Inputs!$B$8*E28,Inputs!$B$9*Inputs!$B$8*INDEX(Inputs!$E$23:$E$32,B28)*Inputs!$B$4^7) | G28: =IF(C28=1,F28/Inputs!$B$4,F27) | H28: =IF(C28=1,G28,Inputs!$B$7*F27) | I28: =H28/D28/3600 | J28: =(F28-G28)/(Inputs!$B$6*D28)/3600 | K28: =I28+J28 | L28: =L27+K28 | M28: =L28/(Inputs!$B$10*Inputs!$B$11) | N28: =(L28-K28)/(Inputs!$B$10*Inputs!$B$11)
A29: =Inputs!$C$25&" 8" | B29: 3 | C29: 8 | D29: =INDEX(Inputs!$F$23:$F$32,B29)*Inputs!$B$5^(C29-1)*INDEX(EXT_Budget!$K$4:$K$13,B29) | E29: =INDEX(Inputs!$E$23:$E$32,B29)*Inputs!$B$4^(C29-1) | F29: =IF(C29<9,Inputs!$B$8*E29,Inputs!$B$9*Inputs!$B$8*INDEX(Inputs!$E$23:$E$32,B29)*Inputs!$B$4^7) | G29: =IF(C29=1,F29/Inputs!$B$4,F28) | H29: =IF(C29=1,G29,Inputs!$B$7*F28) | I29: =H29/D29/3600 | J29: =(F29-G29)/(Inputs!$B$6*D29)/3600 | K29: =I29+J29 | L29: =L28+K29 | M29: =L29/(Inputs!$B$10*Inputs!$B$11) | N29: =(L29-K29)/(Inputs!$B$10*Inputs!$B$11)
A30: =Inputs!$C$25&" 9" | B30: 3 | C30: 9 | D30: =INDEX(Inputs!$F$23:$F$32,B30)*Inputs!$B$5^(C30-1)*INDEX(EXT_Budget!$K$4:$K$13,B30) | E30: =INDEX(Inputs!$E$23:$E$32,B30)*Inputs!$B$4^(C30-1) | F30: =IF(C30<9,Inputs!$B$8*E30,Inputs!$B$9*Inputs!$B$8*INDEX(Inputs!$E$23:$E$32,B30)*Inputs!$B$4^7) | G30: =IF(C30=1,F30/Inputs!$B$4,F29) | H30: =IF(C30=1,G30,Inputs!$B$7*F29) | I30: =H30/D30/3600 | J30: =(F30-G30)/(Inputs!$B$6*D30)/3600 | K30: =I30+J30 | L30: =L29+K30 | M30: =L30/(Inputs!$B$10*Inputs!$B$11) | N30: =(L30-K30)/(Inputs!$B$10*Inputs!$B$11)
A31: =Inputs!$C$26&" 1" | B31: 4 | C31: 1 | D31: =INDEX(Inputs!$F$23:$F$32,B31)*Inputs!$B$5^(C31-1)*INDEX(EXT_Budget!$K$4:$K$13,B31) | E31: =INDEX(Inputs!$E$23:$E$32,B31)*Inputs!$B$4^(C31-1) | F31: =IF(C31<9,Inputs!$B$8*E31,Inputs!$B$9*Inputs!$B$8*INDEX(Inputs!$E$23:$E$32,B31)*Inputs!$B$4^7) | G31: =IF(C31=1,F31/Inputs!$B$4,F30) | H31: =IF(C31=1,G31,Inputs!$B$7*F30) | I31: =H31/D31/3600 | J31: =(F31-G31)/(Inputs!$B$6*D31)/3600 | K31: =I31+J31 | L31: =L30+K31 | M31: =L31/(Inputs!$B$10*Inputs!$B$11) | N31: =(L31-K31)/(Inputs!$B$10*Inputs!$B$11)
A32: =Inputs!$C$26&" 2" | B32: 4 | C32: 2 | D32: =INDEX(Inputs!$F$23:$F$32,B32)*Inputs!$B$5^(C32-1)*INDEX(EXT_Budget!$K$4:$K$13,B32) | E32: =INDEX(Inputs!$E$23:$E$32,B32)*Inputs!$B$4^(C32-1) | F32: =IF(C32<9,Inputs!$B$8*E32,Inputs!$B$9*Inputs!$B$8*INDEX(Inputs!$E$23:$E$32,B32)*Inputs!$B$4^7) | G32: =IF(C32=1,F32/Inputs!$B$4,F31) | H32: =IF(C32=1,G32,Inputs!$B$7*F31) | I32: =H32/D32/3600 | J32: =(F32-G32)/(Inputs!$B$6*D32)/3600 | K32: =I32+J32 | L32: =L31+K32 | M32: =L32/(Inputs!$B$10*Inputs!$B$11) | N32: =(L32-K32)/(Inputs!$B$10*Inputs!$B$11)
A33: =Inputs!$C$26&" 3" | B33: 4 | C33: 3 | D33: =INDEX(Inputs!$F$23:$F$32,B33)*Inputs!$B$5^(C33-1)*INDEX(EXT_Budget!$K$4:$K$13,B33) | E33: =INDEX(Inputs!$E$23:$E$32,B33)*Inputs!$B$4^(C33-1) | F33: =IF(C33<9,Inputs!$B$8*E33,Inputs!$B$9*Inputs!$B$8*INDEX(Inputs!$E$23:$E$32,B33)*Inputs!$B$4^7) | G33: =IF(C33=1,F33/Inputs!$B$4,F32) | H33: =IF(C33=1,G33,Inputs!$B$7*F32) | I33: =H33/D33/3600 | J33: =(F33-G33)/(Inputs!$B$6*D33)/3600 | K33: =I33+J33 | L33: =L32+K33 | M33: =L33/(Inputs!$B$10*Inputs!$B$11) | N33: =(L33-K33)/(Inputs!$B$10*Inputs!$B$11)
A34: =Inputs!$C$26&" 4" | B34: 4 | C34: 4 | D34: =INDEX(Inputs!$F$23:$F$32,B34)*Inputs!$B$5^(C34-1)*INDEX(EXT_Budget!$K$4:$K$13,B34) | E34: =INDEX(Inputs!$E$23:$E$32,B34)*Inputs!$B$4^(C34-1) | F34: =IF(C34<9,Inputs!$B$8*E34,Inputs!$B$9*Inputs!$B$8*INDEX(Inputs!$E$23:$E$32,B34)*Inputs!$B$4^7) | G34: =IF(C34=1,F34/Inputs!$B$4,F33) | H34: =IF(C34=1,G34,Inputs!$B$7*F33) | I34: =H34/D34/3600 | J34: =(F34-G34)/(Inputs!$B$6*D34)/3600 | K34: =I34+J34 | L34: =L33+K34 | M34: =L34/(Inputs!$B$10*Inputs!$B$11) | N34: =(L34-K34)/(Inputs!$B$10*Inputs!$B$11)
A35: =Inputs!$C$26&" 5" | B35: 4 | C35: 5 | D35: =INDEX(Inputs!$F$23:$F$32,B35)*Inputs!$B$5^(C35-1)*INDEX(EXT_Budget!$K$4:$K$13,B35) | E35: =INDEX(Inputs!$E$23:$E$32,B35)*Inputs!$B$4^(C35-1) | F35: =IF(C35<9,Inputs!$B$8*E35,Inputs!$B$9*Inputs!$B$8*INDEX(Inputs!$E$23:$E$32,B35)*Inputs!$B$4^7) | G35: =IF(C35=1,F35/Inputs!$B$4,F34) | H35: =IF(C35=1,G35,Inputs!$B$7*F34) | I35: =H35/D35/3600 | J35: =(F35-G35)/(Inputs!$B$6*D35)/3600 | K35: =I35+J35 | L35: =L34+K35 | M35: =L35/(Inputs!$B$10*Inputs!$B$11) | N35: =(L35-K35)/(Inputs!$B$10*Inputs!$B$11)
A36: =Inputs!$C$26&" 6" | B36: 4 | C36: 6 | D36: =INDEX(Inputs!$F$23:$F$32,B36)*Inputs!$B$5^(C36-1)*INDEX(EXT_Budget!$K$4:$K$13,B36) | E36: =INDEX(Inputs!$E$23:$E$32,B36)*Inputs!$B$4^(C36-1) | F36: =IF(C36<9,Inputs!$B$8*E36,Inputs!$B$9*Inputs!$B$8*INDEX(Inputs!$E$23:$E$32,B36)*Inputs!$B$4^7) | G36: =IF(C36=1,F36/Inputs!$B$4,F35) | H36: =IF(C36=1,G36,Inputs!$B$7*F35) | I36: =H36/D36/3600 | J36: =(F36-G36)/(Inputs!$B$6*D36)/3600 | K36: =I36+J36 | L36: =L35+K36 | M36: =L36/(Inputs!$B$10*Inputs!$B$11) | N36: =(L36-K36)/(Inputs!$B$10*Inputs!$B$11)
A37: =Inputs!$C$26&" 7" | B37: 4 | C37: 7 | D37: =INDEX(Inputs!$F$23:$F$32,B37)*Inputs!$B$5^(C37-1)*INDEX(EXT_Budget!$K$4:$K$13,B37) | E37: =INDEX(Inputs!$E$23:$E$32,B37)*Inputs!$B$4^(C37-1) | F37: =IF(C37<9,Inputs!$B$8*E37,Inputs!$B$9*Inputs!$B$8*INDEX(Inputs!$E$23:$E$32,B37)*Inputs!$B$4^7) | G37: =IF(C37=1,F37/Inputs!$B$4,F36) | H37: =IF(C37=1,G37,Inputs!$B$7*F36) | I37: =H37/D37/3600 | J37: =(F37-G37)/(Inputs!$B$6*D37)/3600 | K37: =I37+J37 | L37: =L36+K37 | M37: =L37/(Inputs!$B$10*Inputs!$B$11) | N37: =(L37-K37)/(Inputs!$B$10*Inputs!$B$11)
A38: =Inputs!$C$26&" 8" | B38: 4 | C38: 8 | D38: =INDEX(Inputs!$F$23:$F$32,B38)*Inputs!$B$5^(C38-1)*INDEX(EXT_Budget!$K$4:$K$13,B38) | E38: =INDEX(Inputs!$E$23:$E$32,B38)*Inputs!$B$4^(C38-1) | F38: =IF(C38<9,Inputs!$B$8*E38,Inputs!$B$9*Inputs!$B$8*INDEX(Inputs!$E$23:$E$32,B38)*Inputs!$B$4^7) | G38: =IF(C38=1,F38/Inputs!$B$4,F37) | H38: =IF(C38=1,G38,Inputs!$B$7*F37) | I38: =H38/D38/3600 | J38: =(F38-G38)/(Inputs!$B$6*D38)/3600 | K38: =I38+J38 | L38: =L37+K38 | M38: =L38/(Inputs!$B$10*Inputs!$B$11) | N38: =(L38-K38)/(Inputs!$B$10*Inputs!$B$11)
A39: =Inputs!$C$26&" 9" | B39: 4 | C39: 9 | D39: =INDEX(Inputs!$F$23:$F$32,B39)*Inputs!$B$5^(C39-1)*INDEX(EXT_Budget!$K$4:$K$13,B39) | E39: =INDEX(Inputs!$E$23:$E$32,B39)*Inputs!$B$4^(C39-1) | F39: =IF(C39<9,Inputs!$B$8*E39,Inputs!$B$9*Inputs!$B$8*INDEX(Inputs!$E$23:$E$32,B39)*Inputs!$B$4^7) | G39: =IF(C39=1,F39/Inputs!$B$4,F38) | H39: =IF(C39=1,G39,Inputs!$B$7*F38) | I39: =H39/D39/3600 | J39: =(F39-G39)/(Inputs!$B$6*D39)/3600 | K39: =I39+J39 | L39: =L38+K39 | M39: =L39/(Inputs!$B$10*Inputs!$B$11) | N39: =(L39-K39)/(Inputs!$B$10*Inputs!$B$11)
A40: =Inputs!$C$27&" 1" | B40: 5 | C40: 1 | D40: =INDEX(Inputs!$F$23:$F$32,B40)*Inputs!$B$5^(C40-1)*INDEX(EXT_Budget!$K$4:$K$13,B40) | E40: =INDEX(Inputs!$E$23:$E$32,B40)*Inputs!$B$4^(C40-1) | F40: =IF(C40<9,Inputs!$B$8*E40,Inputs!$B$9*Inputs!$B$8*INDEX(Inputs!$E$23:$E$32,B40)*Inputs!$B$4^7) | G40: =IF(C40=1,F40/Inputs!$B$4,F39) | H40: =IF(C40=1,G40,Inputs!$B$7*F39) | I40: =H40/D40/3600 | J40: =(F40-G40)/(Inputs!$B$6*D40)/3600 | K40: =I40+J40 | L40: =L39+K40 | M40: =L40/(Inputs!$B$10*Inputs!$B$11) | N40: =(L40-K40)/(Inputs!$B$10*Inputs!$B$11)
A41: =Inputs!$C$27&" 2" | B41: 5 | C41: 2 | D41: =INDEX(Inputs!$F$23:$F$32,B41)*Inputs!$B$5^(C41-1)*INDEX(EXT_Budget!$K$4:$K$13,B41) | E41: =INDEX(Inputs!$E$23:$E$32,B41)*Inputs!$B$4^(C41-1) | F41: =IF(C41<9,Inputs!$B$8*E41,Inputs!$B$9*Inputs!$B$8*INDEX(Inputs!$E$23:$E$32,B41)*Inputs!$B$4^7) | G41: =IF(C41=1,F41/Inputs!$B$4,F40) | H41: =IF(C41=1,G41,Inputs!$B$7*F40) | I41: =H41/D41/3600 | J41: =(F41-G41)/(Inputs!$B$6*D41)/3600 | K41: =I41+J41 | L41: =L40+K41 | M41: =L41/(Inputs!$B$10*Inputs!$B$11) | N41: =(L41-K41)/(Inputs!$B$10*Inputs!$B$11)
...

Sheet Body_Pacing
A1: Body pacing (Vessel Model, Train time)
A3: Key | B3: Idx | C3: Level | D3: Rate /s | E3: Work | F3: Cap (max at level end) | G3: Start max | H3: Refill amount | I3: Refill h | J3: Growth h | K3: Level h | L3: Cumulative h | M3: Day (end of level) | N3: Day (level reached)
A4: =Inputs!$B$38&" 1" | B4: 1 | C4: 1 | D4: =Inputs!$B$16^(B4-1)*Inputs!$B$5^(C4-1)*INDEX(Inputs!$D$38:$D$44,B4) | E4: =INDEX(Inputs!$C$38:$C$44,B4)*Inputs!$B$4^(C4-1) | F4: =IF(C4<9,Inputs!$B$8*E4,Inputs!$B$9*Inputs!$B$8*INDEX(Inputs!$C$38:$C$44,B4)*Inputs!$B$4^7) | G4: =F4/Inputs!$B$4 | H4: =G4 | I4: =H4/D4/3600 | J4: =(F4-G4)/(Inputs!$B$6*D4)/3600 | K4: =I4+J4 | L4: =K4 | M4: =L4/(Inputs!$B$10*Inputs!$B$12) | N4: =(L4-K4)/(Inputs!$B$10*Inputs!$B$12)
A5: =Inputs!$B$38&" 2" | B5: 1 | C5: 2 | D5: =Inputs!$B$16^(B5-1)*Inputs!$B$5^(C5-1)*INDEX(Inputs!$D$38:$D$44,B5) | E5: =INDEX(Inputs!$C$38:$C$44,B5)*Inputs!$B$4^(C5-1) | F5: =IF(C5<9,Inputs!$B$8*E5,Inputs!$B$9*Inputs!$B$8*INDEX(Inputs!$C$38:$C$44,B5)*Inputs!$B$4^7) | G5: =IF(C5=1,F5/Inputs!$B$4,F4) | H5: =IF(C5=1,G5,Inputs!$B$7*F4) | I5: =H5/D5/3600 | J5: =(F5-G5)/(Inputs!$B$6*D5)/3600 | K5: =I5+J5 | L5: =L4+K5 | M5: =L5/(Inputs!$B$10*Inputs!$B$12) | N5: =(L5-K5)/(Inputs!$B$10*Inputs!$B$12)
A6: =Inputs!$B$38&" 3" | B6: 1 | C6: 3 | D6: =Inputs!$B$16^(B6-1)*Inputs!$B$5^(C6-1)*INDEX(Inputs!$D$38:$D$44,B6) | E6: =INDEX(Inputs!$C$38:$C$44,B6)*Inputs!$B$4^(C6-1) | F6: =IF(C6<9,Inputs!$B$8*E6,Inputs!$B$9*Inputs!$B$8*INDEX(Inputs!$C$38:$C$44,B6)*Inputs!$B$4^7) | G6: =IF(C6=1,F6/Inputs!$B$4,F5) | H6: =IF(C6=1,G6,Inputs!$B$7*F5) | I6: =H6/D6/3600 | J6: =(F6-G6)/(Inputs!$B$6*D6)/3600 | K6: =I6+J6 | L6: =L5+K6 | M6: =L6/(Inputs!$B$10*Inputs!$B$12) | N6: =(L6-K6)/(Inputs!$B$10*Inputs!$B$12)
A7: =Inputs!$B$38&" 4" | B7: 1 | C7: 4 | D7: =Inputs!$B$16^(B7-1)*Inputs!$B$5^(C7-1)*INDEX(Inputs!$D$38:$D$44,B7) | E7: =INDEX(Inputs!$C$38:$C$44,B7)*Inputs!$B$4^(C7-1) | F7: =IF(C7<9,Inputs!$B$8*E7,Inputs!$B$9*Inputs!$B$8*INDEX(Inputs!$C$38:$C$44,B7)*Inputs!$B$4^7) | G7: =IF(C7=1,F7/Inputs!$B$4,F6) | H7: =IF(C7=1,G7,Inputs!$B$7*F6) | I7: =H7/D7/3600 | J7: =(F7-G7)/(Inputs!$B$6*D7)/3600 | K7: =I7+J7 | L7: =L6+K7 | M7: =L7/(Inputs!$B$10*Inputs!$B$12) | N7: =(L7-K7)/(Inputs!$B$10*Inputs!$B$12)
A8: =Inputs!$B$38&" 5" | B8: 1 | C8: 5 | D8: =Inputs!$B$16^(B8-1)*Inputs!$B$5^(C8-1)*INDEX(Inputs!$D$38:$D$44,B8) | E8: =INDEX(Inputs!$C$38:$C$44,B8)*Inputs!$B$4^(C8-1) | F8: =IF(C8<9,Inputs!$B$8*E8,Inputs!$B$9*Inputs!$B$8*INDEX(Inputs!$C$38:$C$44,B8)*Inputs!$B$4^7) | G8: =IF(C8=1,F8/Inputs!$B$4,F7) | H8: =IF(C8=1,G8,Inputs!$B$7*F7) | I8: =H8/D8/3600 | J8: =(F8-G8)/(Inputs!$B$6*D8)/3600 | K8: =I8+J8 | L8: =L7+K8 | M8: =L8/(Inputs!$B$10*Inputs!$B$12) | N8: =(L8-K8)/(Inputs!$B$10*Inputs!$B$12)
A9: =Inputs!$B$38&" 6" | B9: 1 | C9: 6 | D9: =Inputs!$B$16^(B9-1)*Inputs!$B$5^(C9-1)*INDEX(Inputs!$D$38:$D$44,B9) | E9: =INDEX(Inputs!$C$38:$C$44,B9)*Inputs!$B$4^(C9-1) | F9: =IF(C9<9,Inputs!$B$8*E9,Inputs!$B$9*Inputs!$B$8*INDEX(Inputs!$C$38:$C$44,B9)*Inputs!$B$4^7) | G9: =IF(C9=1,F9/Inputs!$B$4,F8) | H9: =IF(C9=1,G9,Inputs!$B$7*F8) | I9: =H9/D9/3600 | J9: =(F9-G9)/(Inputs!$B$6*D9)/3600 | K9: =I9+J9 | L9: =L8+K9 | M9: =L9/(Inputs!$B$10*Inputs!$B$12) | N9: =(L9-K9)/(Inputs!$B$10*Inputs!$B$12)
A10: =Inputs!$B$38&" 7" | B10: 1 | C10: 7 | D10: =Inputs!$B$16^(B10-1)*Inputs!$B$5^(C10-1)*INDEX(Inputs!$D$38:$D$44,B10) | E10: =INDEX(Inputs!$C$38:$C$44,B10)*Inputs!$B$4^(C10-1) | F10: =IF(C10<9,Inputs!$B$8*E10,Inputs!$B$9*Inputs!$B$8*INDEX(Inputs!$C$38:$C$44,B10)*Inputs!$B$4^7) | G10: =IF(C10=1,F10/Inputs!$B$4,F9) | H10: =IF(C10=1,G10,Inputs!$B$7*F9) | I10: =H10/D10/3600 | J10: =(F10-G10)/(Inputs!$B$6*D10)/3600 | K10: =I10+J10 | L10: =L9+K10 | M10: =L10/(Inputs!$B$10*Inputs!$B$12) | N10: =(L10-K10)/(Inputs!$B$10*Inputs!$B$12)
A11: =Inputs!$B$38&" 8" | B11: 1 | C11: 8 | D11: =Inputs!$B$16^(B11-1)*Inputs!$B$5^(C11-1)*INDEX(Inputs!$D$38:$D$44,B11) | E11: =INDEX(Inputs!$C$38:$C$44,B11)*Inputs!$B$4^(C11-1) | F11: =IF(C11<9,Inputs!$B$8*E11,Inputs!$B$9*Inputs!$B$8*INDEX(Inputs!$C$38:$C$44,B11)*Inputs!$B$4^7) | G11: =IF(C11=1,F11/Inputs!$B$4,F10) | H11: =IF(C11=1,G11,Inputs!$B$7*F10) | I11: =H11/D11/3600 | J11: =(F11-G11)/(Inputs!$B$6*D11)/3600 | K11: =I11+J11 | L11: =L10+K11 | M11: =L11/(Inputs!$B$10*Inputs!$B$12) | N11: =(L11-K11)/(Inputs!$B$10*Inputs!$B$12)
A12: =Inputs!$B$38&" 9" | B12: 1 | C12: 9 | D12: =Inputs!$B$16^(B12-1)*Inputs!$B$5^(C12-1)*INDEX(Inputs!$D$38:$D$44,B12) | E12: =INDEX(Inputs!$C$38:$C$44,B12)*Inputs!$B$4^(C12-1) | F12: =IF(C12<9,Inputs!$B$8*E12,Inputs!$B$9*Inputs!$B$8*INDEX(Inputs!$C$38:$C$44,B12)*Inputs!$B$4^7) | G12: =IF(C12=1,F12/Inputs!$B$4,F11) | H12: =IF(C12=1,G12,Inputs!$B$7*F11) | I12: =H12/D12/3600 | J12: =(F12-G12)/(Inputs!$B$6*D12)/3600 | K12: =I12+J12 | L12: =L11+K12 | M12: =L12/(Inputs!$B$10*Inputs!$B$12) | N12: =(L12-K12)/(Inputs!$B$10*Inputs!$B$12)
A13: =Inputs!$B$39&" 1" | B13: 2 | C13: 1 | D13: =Inputs!$B$16^(B13-1)*Inputs!$B$5^(C13-1)*INDEX(Inputs!$D$38:$D$44,B13) | E13: =INDEX(Inputs!$C$38:$C$44,B13)*Inputs!$B$4^(C13-1) | F13: =IF(C13<9,Inputs!$B$8*E13,Inputs!$B$9*Inputs!$B$8*INDEX(Inputs!$C$38:$C$44,B13)*Inputs!$B$4^7) | G13: =IF(C13=1,F13/Inputs!$B$4,F12) | H13: =IF(C13=1,G13,Inputs!$B$7*F12) | I13: =H13/D13/3600 | J13: =(F13-G13)/(Inputs!$B$6*D13)/3600 | K13: =I13+J13 | L13: =L12+K13 | M13: =L13/(Inputs!$B$10*Inputs!$B$12) | N13: =(L13-K13)/(Inputs!$B$10*Inputs!$B$12)
A14: =Inputs!$B$39&" 2" | B14: 2 | C14: 2 | D14: =Inputs!$B$16^(B14-1)*Inputs!$B$5^(C14-1)*INDEX(Inputs!$D$38:$D$44,B14) | E14: =INDEX(Inputs!$C$38:$C$44,B14)*Inputs!$B$4^(C14-1) | F14: =IF(C14<9,Inputs!$B$8*E14,Inputs!$B$9*Inputs!$B$8*INDEX(Inputs!$C$38:$C$44,B14)*Inputs!$B$4^7) | G14: =IF(C14=1,F14/Inputs!$B$4,F13) | H14: =IF(C14=1,G14,Inputs!$B$7*F13) | I14: =H14/D14/3600 | J14: =(F14-G14)/(Inputs!$B$6*D14)/3600 | K14: =I14+J14 | L14: =L13+K14 | M14: =L14/(Inputs!$B$10*Inputs!$B$12) | N14: =(L14-K14)/(Inputs!$B$10*Inputs!$B$12)
A15: =Inputs!$B$39&" 3" | B15: 2 | C15: 3 | D15: =Inputs!$B$16^(B15-1)*Inputs!$B$5^(C15-1)*INDEX(Inputs!$D$38:$D$44,B15) | E15: =INDEX(Inputs!$C$38:$C$44,B15)*Inputs!$B$4^(C15-1) | F15: =IF(C15<9,Inputs!$B$8*E15,Inputs!$B$9*Inputs!$B$8*INDEX(Inputs!$C$38:$C$44,B15)*Inputs!$B$4^7) | G15: =IF(C15=1,F15/Inputs!$B$4,F14) | H15: =IF(C15=1,G15,Inputs!$B$7*F14) | I15: =H15/D15/3600 | J15: =(F15-G15)/(Inputs!$B$6*D15)/3600 | K15: =I15+J15 | L15: =L14+K15 | M15: =L15/(Inputs!$B$10*Inputs!$B$12) | N15: =(L15-K15)/(Inputs!$B$10*Inputs!$B$12)
A16: =Inputs!$B$39&" 4" | B16: 2 | C16: 4 | D16: =Inputs!$B$16^(B16-1)*Inputs!$B$5^(C16-1)*INDEX(Inputs!$D$38:$D$44,B16) | E16: =INDEX(Inputs!$C$38:$C$44,B16)*Inputs!$B$4^(C16-1) | F16: =IF(C16<9,Inputs!$B$8*E16,Inputs!$B$9*Inputs!$B$8*INDEX(Inputs!$C$38:$C$44,B16)*Inputs!$B$4^7) | G16: =IF(C16=1,F16/Inputs!$B$4,F15) | H16: =IF(C16=1,G16,Inputs!$B$7*F15) | I16: =H16/D16/3600 | J16: =(F16-G16)/(Inputs!$B$6*D16)/3600 | K16: =I16+J16 | L16: =L15+K16 | M16: =L16/(Inputs!$B$10*Inputs!$B$12) | N16: =(L16-K16)/(Inputs!$B$10*Inputs!$B$12)
A17: =Inputs!$B$39&" 5" | B17: 2 | C17: 5 | D17: =Inputs!$B$16^(B17-1)*Inputs!$B$5^(C17-1)*INDEX(Inputs!$D$38:$D$44,B17) | E17: =INDEX(Inputs!$C$38:$C$44,B17)*Inputs!$B$4^(C17-1) | F17: =IF(C17<9,Inputs!$B$8*E17,Inputs!$B$9*Inputs!$B$8*INDEX(Inputs!$C$38:$C$44,B17)*Inputs!$B$4^7) | G17: =IF(C17=1,F17/Inputs!$B$4,F16) | H17: =IF(C17=1,G17,Inputs!$B$7*F16) | I17: =H17/D17/3600 | J17: =(F17-G17)/(Inputs!$B$6*D17)/3600 | K17: =I17+J17 | L17: =L16+K17 | M17: =L17/(Inputs!$B$10*Inputs!$B$12) | N17: =(L17-K17)/(Inputs!$B$10*Inputs!$B$12)
A18: =Inputs!$B$39&" 6" | B18: 2 | C18: 6 | D18: =Inputs!$B$16^(B18-1)*Inputs!$B$5^(C18-1)*INDEX(Inputs!$D$38:$D$44,B18) | E18: =INDEX(Inputs!$C$38:$C$44,B18)*Inputs!$B$4^(C18-1) | F18: =IF(C18<9,Inputs!$B$8*E18,Inputs!$B$9*Inputs!$B$8*INDEX(Inputs!$C$38:$C$44,B18)*Inputs!$B$4^7) | G18: =IF(C18=1,F18/Inputs!$B$4,F17) | H18: =IF(C18=1,G18,Inputs!$B$7*F17) | I18: =H18/D18/3600 | J18: =(F18-G18)/(Inputs!$B$6*D18)/3600 | K18: =I18+J18 | L18: =L17+K18 | M18: =L18/(Inputs!$B$10*Inputs!$B$12) | N18: =(L18-K18)/(Inputs!$B$10*Inputs!$B$12)
A19: =Inputs!$B$39&" 7" | B19: 2 | C19: 7 | D19: =Inputs!$B$16^(B19-1)*Inputs!$B$5^(C19-1)*INDEX(Inputs!$D$38:$D$44,B19) | E19: =INDEX(Inputs!$C$38:$C$44,B19)*Inputs!$B$4^(C19-1) | F19: =IF(C19<9,Inputs!$B$8*E19,Inputs!$B$9*Inputs!$B$8*INDEX(Inputs!$C$38:$C$44,B19)*Inputs!$B$4^7) | G19: =IF(C19=1,F19/Inputs!$B$4,F18) | H19: =IF(C19=1,G19,Inputs!$B$7*F18) | I19: =H19/D19/3600 | J19: =(F19-G19)/(Inputs!$B$6*D19)/3600 | K19: =I19+J19 | L19: =L18+K19 | M19: =L19/(Inputs!$B$10*Inputs!$B$12) | N19: =(L19-K19)/(Inputs!$B$10*Inputs!$B$12)
A20: =Inputs!$B$39&" 8" | B20: 2 | C20: 8 | D20: =Inputs!$B$16^(B20-1)*Inputs!$B$5^(C20-1)*INDEX(Inputs!$D$38:$D$44,B20) | E20: =INDEX(Inputs!$C$38:$C$44,B20)*Inputs!$B$4^(C20-1) | F20: =IF(C20<9,Inputs!$B$8*E20,Inputs!$B$9*Inputs!$B$8*INDEX(Inputs!$C$38:$C$44,B20)*Inputs!$B$4^7) | G20: =IF(C20=1,F20/Inputs!$B$4,F19) | H20: =IF(C20=1,G20,Inputs!$B$7*F19) | I20: =H20/D20/3600 | J20: =(F20-G20)/(Inputs!$B$6*D20)/3600 | K20: =I20+J20 | L20: =L19+K20 | M20: =L20/(Inputs!$B$10*Inputs!$B$12) | N20: =(L20-K20)/(Inputs!$B$10*Inputs!$B$12)
A21: =Inputs!$B$39&" 9" | B21: 2 | C21: 9 | D21: =Inputs!$B$16^(B21-1)*Inputs!$B$5^(C21-1)*INDEX(Inputs!$D$38:$D$44,B21) | E21: =INDEX(Inputs!$C$38:$C$44,B21)*Inputs!$B$4^(C21-1) | F21: =IF(C21<9,Inputs!$B$8*E21,Inputs!$B$9*Inputs!$B$8*INDEX(Inputs!$C$38:$C$44,B21)*Inputs!$B$4^7) | G21: =IF(C21=1,F21/Inputs!$B$4,F20) | H21: =IF(C21=1,G21,Inputs!$B$7*F20) | I21: =H21/D21/3600 | J21: =(F21-G21)/(Inputs!$B$6*D21)/3600 | K21: =I21+J21 | L21: =L20+K21 | M21: =L21/(Inputs!$B$10*Inputs!$B$12) | N21: =(L21-K21)/(Inputs!$B$10*Inputs!$B$12)
A22: =Inputs!$B$40&" 1" | B22: 3 | C22: 1 | D22: =Inputs!$B$16^(B22-1)*Inputs!$B$5^(C22-1)*INDEX(Inputs!$D$38:$D$44,B22) | E22: =INDEX(Inputs!$C$38:$C$44,B22)*Inputs!$B$4^(C22-1) | F22: =IF(C22<9,Inputs!$B$8*E22,Inputs!$B$9*Inputs!$B$8*INDEX(Inputs!$C$38:$C$44,B22)*Inputs!$B$4^7) | G22: =IF(C22=1,F22/Inputs!$B$4,F21) | H22: =IF(C22=1,G22,Inputs!$B$7*F21) | I22: =H22/D22/3600 | J22: =(F22-G22)/(Inputs!$B$6*D22)/3600 | K22: =I22+J22 | L22: =L21+K22 | M22: =L22/(Inputs!$B$10*Inputs!$B$12) | N22: =(L22-K22)/(Inputs!$B$10*Inputs!$B$12)
A23: =Inputs!$B$40&" 2" | B23: 3 | C23: 2 | D23: =Inputs!$B$16^(B23-1)*Inputs!$B$5^(C23-1)*INDEX(Inputs!$D$38:$D$44,B23) | E23: =INDEX(Inputs!$C$38:$C$44,B23)*Inputs!$B$4^(C23-1) | F23: =IF(C23<9,Inputs!$B$8*E23,Inputs!$B$9*Inputs!$B$8*INDEX(Inputs!$C$38:$C$44,B23)*Inputs!$B$4^7) | G23: =IF(C23=1,F23/Inputs!$B$4,F22) | H23: =IF(C23=1,G23,Inputs!$B$7*F22) | I23: =H23/D23/3600 | J23: =(F23-G23)/(Inputs!$B$6*D23)/3600 | K23: =I23+J23 | L23: =L22+K23 | M23: =L23/(Inputs!$B$10*Inputs!$B$12) | N23: =(L23-K23)/(Inputs!$B$10*Inputs!$B$12)
A24: =Inputs!$B$40&" 3" | B24: 3 | C24: 3 | D24: =Inputs!$B$16^(B24-1)*Inputs!$B$5^(C24-1)*INDEX(Inputs!$D$38:$D$44,B24) | E24: =INDEX(Inputs!$C$38:$C$44,B24)*Inputs!$B$4^(C24-1) | F24: =IF(C24<9,Inputs!$B$8*E24,Inputs!$B$9*Inputs!$B$8*INDEX(Inputs!$C$38:$C$44,B24)*Inputs!$B$4^7) | G24: =IF(C24=1,F24/Inputs!$B$4,F23) | H24: =IF(C24=1,G24,Inputs!$B$7*F23) | I24: =H24/D24/3600 | J24: =(F24-G24)/(Inputs!$B$6*D24)/3600 | K24: =I24+J24 | L24: =L23+K24 | M24: =L24/(Inputs!$B$10*Inputs!$B$12) | N24: =(L24-K24)/(Inputs!$B$10*Inputs!$B$12)
A25: =Inputs!$B$40&" 4" | B25: 3 | C25: 4 | D25: =Inputs!$B$16^(B25-1)*Inputs!$B$5^(C25-1)*INDEX(Inputs!$D$38:$D$44,B25) | E25: =INDEX(Inputs!$C$38:$C$44,B25)*Inputs!$B$4^(C25-1) | F25: =IF(C25<9,Inputs!$B$8*E25,Inputs!$B$9*Inputs!$B$8*INDEX(Inputs!$C$38:$C$44,B25)*Inputs!$B$4^7) | G25: =IF(C25=1,F25/Inputs!$B$4,F24) | H25: =IF(C25=1,G25,Inputs!$B$7*F24) | I25: =H25/D25/3600 | J25: =(F25-G25)/(Inputs!$B$6*D25)/3600 | K25: =I25+J25 | L25: =L24+K25 | M25: =L25/(Inputs!$B$10*Inputs!$B$12) | N25: =(L25-K25)/(Inputs!$B$10*Inputs!$B$12)
A26: =Inputs!$B$40&" 5" | B26: 3 | C26: 5 | D26: =Inputs!$B$16^(B26-1)*Inputs!$B$5^(C26-1)*INDEX(Inputs!$D$38:$D$44,B26) | E26: =INDEX(Inputs!$C$38:$C$44,B26)*Inputs!$B$4^(C26-1) | F26: =IF(C26<9,Inputs!$B$8*E26,Inputs!$B$9*Inputs!$B$8*INDEX(Inputs!$C$38:$C$44,B26)*Inputs!$B$4^7) | G26: =IF(C26=1,F26/Inputs!$B$4,F25) | H26: =IF(C26=1,G26,Inputs!$B$7*F25) | I26: =H26/D26/3600 | J26: =(F26-G26)/(Inputs!$B$6*D26)/3600 | K26: =I26+J26 | L26: =L25+K26 | M26: =L26/(Inputs!$B$10*Inputs!$B$12) | N26: =(L26-K26)/(Inputs!$B$10*Inputs!$B$12)
A27: =Inputs!$B$40&" 6" | B27: 3 | C27: 6 | D27: =Inputs!$B$16^(B27-1)*Inputs!$B$5^(C27-1)*INDEX(Inputs!$D$38:$D$44,B27) | E27: =INDEX(Inputs!$C$38:$C$44,B27)*Inputs!$B$4^(C27-1) | F27: =IF(C27<9,Inputs!$B$8*E27,Inputs!$B$9*Inputs!$B$8*INDEX(Inputs!$C$38:$C$44,B27)*Inputs!$B$4^7) | G27: =IF(C27=1,F27/Inputs!$B$4,F26) | H27: =IF(C27=1,G27,Inputs!$B$7*F26) | I27: =H27/D27/3600 | J27: =(F27-G27)/(Inputs!$B$6*D27)/3600 | K27: =I27+J27 | L27: =L26+K27 | M27: =L27/(Inputs!$B$10*Inputs!$B$12) | N27: =(L27-K27)/(Inputs!$B$10*Inputs!$B$12)
A28: =Inputs!$B$40&" 7" | B28: 3 | C28: 7 | D28: =Inputs!$B$16^(B28-1)*Inputs!$B$5^(C28-1)*INDEX(Inputs!$D$38:$D$44,B28) | E28: =INDEX(Inputs!$C$38:$C$44,B28)*Inputs!$B$4^(C28-1) | F28: =IF(C28<9,Inputs!$B$8*E28,Inputs!$B$9*Inputs!$B$8*INDEX(Inputs!$C$38:$C$44,B28)*Inputs!$B$4^7) | G28: =IF(C28=1,F28/Inputs!$B$4,F27) | H28: =IF(C28=1,G28,Inputs!$B$7*F27) | I28: =H28/D28/3600 | J28: =(F28-G28)/(Inputs!$B$6*D28)/3600 | K28: =I28+J28 | L28: =L27+K28 | M28: =L28/(Inputs!$B$10*Inputs!$B$12) | N28: =(L28-K28)/(Inputs!$B$10*Inputs!$B$12)
A29: =Inputs!$B$40&" 8" | B29: 3 | C29: 8 | D29: =Inputs!$B$16^(B29-1)*Inputs!$B$5^(C29-1)*INDEX(Inputs!$D$38:$D$44,B29) | E29: =INDEX(Inputs!$C$38:$C$44,B29)*Inputs!$B$4^(C29-1) | F29: =IF(C29<9,Inputs!$B$8*E29,Inputs!$B$9*Inputs!$B$8*INDEX(Inputs!$C$38:$C$44,B29)*Inputs!$B$4^7) | G29: =IF(C29=1,F29/Inputs!$B$4,F28) | H29: =IF(C29=1,G29,Inputs!$B$7*F28) | I29: =H29/D29/3600 | J29: =(F29-G29)/(Inputs!$B$6*D29)/3600 | K29: =I29+J29 | L29: =L28+K29 | M29: =L29/(Inputs!$B$10*Inputs!$B$12) | N29: =(L29-K29)/(Inputs!$B$10*Inputs!$B$12)
A30: =Inputs!$B$40&" 9" | B30: 3 | C30: 9 | D30: =Inputs!$B$16^(B30-1)*Inputs!$B$5^(C30-1)*INDEX(Inputs!$D$38:$D$44,B30) | E30: =INDEX(Inputs!$C$38:$C$44,B30)*Inputs!$B$4^(C30-1) | F30: =IF(C30<9,Inputs!$B$8*E30,Inputs!$B$9*Inputs!$B$8*INDEX(Inputs!$C$38:$C$44,B30)*Inputs!$B$4^7) | G30: =IF(C30=1,F30/Inputs!$B$4,F29) | H30: =IF(C30=1,G30,Inputs!$B$7*F29) | I30: =H30/D30/3600 | J30: =(F30-G30)/(Inputs!$B$6*D30)/3600 | K30: =I30+J30 | L30: =L29+K30 | M30: =L30/(Inputs!$B$10*Inputs!$B$12) | N30: =(L30-K30)/(Inputs!$B$10*Inputs!$B$12)
A31: =Inputs!$B$41&" 1" | B31: 4 | C31: 1 | D31: =Inputs!$B$16^(B31-1)*Inputs!$B$5^(C31-1)*INDEX(Inputs!$D$38:$D$44,B31) | E31: =INDEX(Inputs!$C$38:$C$44,B31)*Inputs!$B$4^(C31-1) | F31: =IF(C31<9,Inputs!$B$8*E31,Inputs!$B$9*Inputs!$B$8*INDEX(Inputs!$C$38:$C$44,B31)*Inputs!$B$4^7) | G31: =IF(C31=1,F31/Inputs!$B$4,F30) | H31: =IF(C31=1,G31,Inputs!$B$7*F30) | I31: =H31/D31/3600 | J31: =(F31-G31)/(Inputs!$B$6*D31)/3600 | K31: =I31+J31 | L31: =L30+K31 | M31: =L31/(Inputs!$B$10*Inputs!$B$12) | N31: =(L31-K31)/(Inputs!$B$10*Inputs!$B$12)
A32: =Inputs!$B$41&" 2" | B32: 4 | C32: 2 | D32: =Inputs!$B$16^(B32-1)*Inputs!$B$5^(C32-1)*INDEX(Inputs!$D$38:$D$44,B32) | E32: =INDEX(Inputs!$C$38:$C$44,B32)*Inputs!$B$4^(C32-1) | F32: =IF(C32<9,Inputs!$B$8*E32,Inputs!$B$9*Inputs!$B$8*INDEX(Inputs!$C$38:$C$44,B32)*Inputs!$B$4^7) | G32: =IF(C32=1,F32/Inputs!$B$4,F31) | H32: =IF(C32=1,G32,Inputs!$B$7*F31) | I32: =H32/D32/3600 | J32: =(F32-G32)/(Inputs!$B$6*D32)/3600 | K32: =I32+J32 | L32: =L31+K32 | M32: =L32/(Inputs!$B$10*Inputs!$B$12) | N32: =(L32-K32)/(Inputs!$B$10*Inputs!$B$12)
A33: =Inputs!$B$41&" 3" | B33: 4 | C33: 3 | D33: =Inputs!$B$16^(B33-1)*Inputs!$B$5^(C33-1)*INDEX(Inputs!$D$38:$D$44,B33) | E33: =INDEX(Inputs!$C$38:$C$44,B33)*Inputs!$B$4^(C33-1) | F33: =IF(C33<9,Inputs!$B$8*E33,Inputs!$B$9*Inputs!$B$8*INDEX(Inputs!$C$38:$C$44,B33)*Inputs!$B$4^7) | G33: =IF(C33=1,F33/Inputs!$B$4,F32) | H33: =IF(C33=1,G33,Inputs!$B$7*F32) | I33: =H33/D33/3600 | J33: =(F33-G33)/(Inputs!$B$6*D33)/3600 | K33: =I33+J33 | L33: =L32+K33 | M33: =L33/(Inputs!$B$10*Inputs!$B$12) | N33: =(L33-K33)/(Inputs!$B$10*Inputs!$B$12)
A34: =Inputs!$B$41&" 4" | B34: 4 | C34: 4 | D34: =Inputs!$B$16^(B34-1)*Inputs!$B$5^(C34-1)*INDEX(Inputs!$D$38:$D$44,B34) | E34: =INDEX(Inputs!$C$38:$C$44,B34)*Inputs!$B$4^(C34-1) | F34: =IF(C34<9,Inputs!$B$8*E34,Inputs!$B$9*Inputs!$B$8*INDEX(Inputs!$C$38:$C$44,B34)*Inputs!$B$4^7) | G34: =IF(C34=1,F34/Inputs!$B$4,F33) | H34: =IF(C34=1,G34,Inputs!$B$7*F33) | I34: =H34/D34/3600 | J34: =(F34-G34)/(Inputs!$B$6*D34)/3600 | K34: =I34+J34 | L34: =L33+K34 | M34: =L34/(Inputs!$B$10*Inputs!$B$12) | N34: =(L34-K34)/(Inputs!$B$10*Inputs!$B$12)
A35: =Inputs!$B$41&" 5" | B35: 4 | C35: 5 | D35: =Inputs!$B$16^(B35-1)*Inputs!$B$5^(C35-1)*INDEX(Inputs!$D$38:$D$44,B35) | E35: =INDEX(Inputs!$C$38:$C$44,B35)*Inputs!$B$4^(C35-1) | F35: =IF(C35<9,Inputs!$B$8*E35,Inputs!$B$9*Inputs!$B$8*INDEX(Inputs!$C$38:$C$44,B35)*Inputs!$B$4^7) | G35: =IF(C35=1,F35/Inputs!$B$4,F34) | H35: =IF(C35=1,G35,Inputs!$B$7*F34) | I35: =H35/D35/3600 | J35: =(F35-G35)/(Inputs!$B$6*D35)/3600 | K35: =I35+J35 | L35: =L34+K35 | M35: =L35/(Inputs!$B$10*Inputs!$B$12) | N35: =(L35-K35)/(Inputs!$B$10*Inputs!$B$12)
A36: =Inputs!$B$41&" 6" | B36: 4 | C36: 6 | D36: =Inputs!$B$16^(B36-1)*Inputs!$B$5^(C36-1)*INDEX(Inputs!$D$38:$D$44,B36) | E36: =INDEX(Inputs!$C$38:$C$44,B36)*Inputs!$B$4^(C36-1) | F36: =IF(C36<9,Inputs!$B$8*E36,Inputs!$B$9*Inputs!$B$8*INDEX(Inputs!$C$38:$C$44,B36)*Inputs!$B$4^7) | G36: =IF(C36=1,F36/Inputs!$B$4,F35) | H36: =IF(C36=1,G36,Inputs!$B$7*F35) | I36: =H36/D36/3600 | J36: =(F36-G36)/(Inputs!$B$6*D36)/3600 | K36: =I36+J36 | L36: =L35+K36 | M36: =L36/(Inputs!$B$10*Inputs!$B$12) | N36: =(L36-K36)/(Inputs!$B$10*Inputs!$B$12)
A37: =Inputs!$B$41&" 7" | B37: 4 | C37: 7 | D37: =Inputs!$B$16^(B37-1)*Inputs!$B$5^(C37-1)*INDEX(Inputs!$D$38:$D$44,B37) | E37: =INDEX(Inputs!$C$38:$C$44,B37)*Inputs!$B$4^(C37-1) | F37: =IF(C37<9,Inputs!$B$8*E37,Inputs!$B$9*Inputs!$B$8*INDEX(Inputs!$C$38:$C$44,B37)*Inputs!$B$4^7) | G37: =IF(C37=1,F37/Inputs!$B$4,F36) | H37: =IF(C37=1,G37,Inputs!$B$7*F36) | I37: =H37/D37/3600 | J37: =(F37-G37)/(Inputs!$B$6*D37)/3600 | K37: =I37+J37 | L37: =L36+K37 | M37: =L37/(Inputs!$B$10*Inputs!$B$12) | N37: =(L37-K37)/(Inputs!$B$10*Inputs!$B$12)
A38: =Inputs!$B$41&" 8" | B38: 4 | C38: 8 | D38: =Inputs!$B$16^(B38-1)*Inputs!$B$5^(C38-1)*INDEX(Inputs!$D$38:$D$44,B38) | E38: =INDEX(Inputs!$C$38:$C$44,B38)*Inputs!$B$4^(C38-1) | F38: =IF(C38<9,Inputs!$B$8*E38,Inputs!$B$9*Inputs!$B$8*INDEX(Inputs!$C$38:$C$44,B38)*Inputs!$B$4^7) | G38: =IF(C38=1,F38/Inputs!$B$4,F37) | H38: =IF(C38=1,G38,Inputs!$B$7*F37) | I38: =H38/D38/3600 | J38: =(F38-G38)/(Inputs!$B$6*D38)/3600 | K38: =I38+J38 | L38: =L37+K38 | M38: =L38/(Inputs!$B$10*Inputs!$B$12) | N38: =(L38-K38)/(Inputs!$B$10*Inputs!$B$12)
A39: =Inputs!$B$41&" 9" | B39: 4 | C39: 9 | D39: =Inputs!$B$16^(B39-1)*Inputs!$B$5^(C39-1)*INDEX(Inputs!$D$38:$D$44,B39) | E39: =INDEX(Inputs!$C$38:$C$44,B39)*Inputs!$B$4^(C39-1) | F39: =IF(C39<9,Inputs!$B$8*E39,Inputs!$B$9*Inputs!$B$8*INDEX(Inputs!$C$38:$C$44,B39)*Inputs!$B$4^7) | G39: =IF(C39=1,F39/Inputs!$B$4,F38) | H39: =IF(C39=1,G39,Inputs!$B$7*F38) | I39: =H39/D39/3600 | J39: =(F39-G39)/(Inputs!$B$6*D39)/3600 | K39: =I39+J39 | L39: =L38+K39 | M39: =L39/(Inputs!$B$10*Inputs!$B$12) | N39: =(L39-K39)/(Inputs!$B$10*Inputs!$B$12)
A40: =Inputs!$B$42&" 1" | B40: 5 | C40: 1 | D40: =Inputs!$B$16^(B40-1)*Inputs!$B$5^(C40-1)*INDEX(Inputs!$D$38:$D$44,B40) | E40: =INDEX(Inputs!$C$38:$C$44,B40)*Inputs!$B$4^(C40-1) | F40: =IF(C40<9,Inputs!$B$8*E40,Inputs!$B$9*Inputs!$B$8*INDEX(Inputs!$C$38:$C$44,B40)*Inputs!$B$4^7) | G40: =IF(C40=1,F40/Inputs!$B$4,F39) | H40: =IF(C40=1,G40,Inputs!$B$7*F39) | I40: =H40/D40/3600 | J40: =(F40-G40)/(Inputs!$B$6*D40)/3600 | K40: =I40+J40 | L40: =L39+K40 | M40: =L40/(Inputs!$B$10*Inputs!$B$12) | N40: =(L40-K40)/(Inputs!$B$10*Inputs!$B$12)
A41: =Inputs!$B$42&" 2" | B41: 5 | C41: 2 | D41: =Inputs!$B$16^(B41-1)*Inputs!$B$5^(C41-1)*INDEX(Inputs!$D$38:$D$44,B41) | E41: =INDEX(Inputs!$C$38:$C$44,B41)*Inputs!$B$4^(C41-1) | F41: =IF(C41<9,Inputs!$B$8*E41,Inputs!$B$9*Inputs!$B$8*INDEX(Inputs!$C$38:$C$44,B41)*Inputs!$B$4^7) | G41: =IF(C41=1,F41/Inputs!$B$4,F40) | H41: =IF(C41=1,G41,Inputs!$B$7*F40) | I41: =H41/D41/3600 | J41: =(F41-G41)/(Inputs!$B$6*D41)/3600 | K41: =I41+J41 | L41: =L40+K41 | M41: =L41/(Inputs!$B$10*Inputs!$B$12) | N41: =(L41-K41)/(Inputs!$B$10*Inputs!$B$12)
...

Sheet Rebirth
A1: Rebirth: stacked gains, Karma, life planner
A3: Qi realm gains (stacked)
A4: Realm | B4: REALM_GAIN | C4: Cumulative before | D4: Gain at level 1 | E4: Gain at peak | F4: Qi Karma (stacked)
A5: =Inputs!C23 | B5: =Inputs!H23 | C5: 0 | D5: =IF(B5=0,0,C5+B5*(0.5+0.5*1/9)) | E5: =C5+B5 | F5: =Inputs!I23
A6: =Inputs!C24 | B6: =Inputs!H24 | C6: =C5+B5 | D6: =IF(B6=0,0,C6+B6*(0.5+0.5*1/9)) | E6: =C6+B6 | F6: =F5+Inputs!I24
A7: =Inputs!C25 | B7: =Inputs!H25 | C7: =C6+B6 | D7: =IF(B7=0,0,C7+B7*(0.5+0.5*1/9)) | E7: =C7+B7 | F7: =F6+Inputs!I25
A8: =Inputs!C26 | B8: =Inputs!H26 | C8: =C7+B7 | D8: =IF(B8=0,0,C8+B8*(0.5+0.5*1/9)) | E8: =C8+B8 | F8: =F7+Inputs!I26
A9: =Inputs!C27 | B9: =Inputs!H27 | C9: =C8+B8 | D9: =IF(B9=0,0,C9+B9*(0.5+0.5*1/9)) | E9: =C9+B9 | F9: =F8+Inputs!I27
A10: =Inputs!C28 | B10: =Inputs!H28 | C10: =C9+B9 | D10: =IF(B10=0,0,C10+B10*(0.5+0.5*1/9)) | E10: =C10+B10 | F10: =F9+Inputs!I28
A11: =Inputs!C29 | B11: =Inputs!H29 | C11: =C10+B10 | D11: =IF(B11=0,0,C11+B11*(0.5+0.5*1/9)) | E11: =C11+B11 | F11: =F10+Inputs!I29
A12: =Inputs!C30 | B12: =Inputs!H30 | C12: =C11+B11 | D12: =IF(B12=0,0,C12+B12*(0.5+0.5*1/9)) | E12: =C12+B12 | F12: =F11+Inputs!I30
A13: =Inputs!C31 | B13: =Inputs!H31 | C13: =C12+B12 | D13: =IF(B13=0,0,C13+B13*(0.5+0.5*1/9)) | E13: =C13+B13 | F13: =F12+Inputs!I31
A14: =Inputs!C32 | B14: =Inputs!H32 | C14: =C13+B13 | D14: =IF(B14=0,0,C14+B14*(0.5+0.5*1/9)) | E14: =C14+B14 | F14: =F13+Inputs!I32
A17: Body stage gains (stacked)
A18: Stage | B18: STAGE_GAIN | C18: Cumulative before | D18: Gain at layer 1 | E18: Gain at peak | F18: Body Karma (stacked)
A19: =Inputs!B38 | B19: =Inputs!F38 | C19: 0 | D19: =IF(B19=0,0,C19+B19*(0.5+0.5*1/9)) | E19: =C19+B19 | F19: =Inputs!G38
A20: =Inputs!B39 | B20: =Inputs!F39 | C20: =C19+B19 | D20: =IF(B20=0,0,C20+B20*(0.5+0.5*1/9)) | E20: =C20+B20 | F20: =F19+Inputs!G39
A21: =Inputs!B40 | B21: =Inputs!F40 | C21: =C20+B20 | D21: =IF(B21=0,0,C21+B21*(0.5+0.5*1/9)) | E21: =C21+B21 | F21: =F20+Inputs!G40
A22: =Inputs!B41 | B22: =Inputs!F41 | C22: =C21+B21 | D22: =IF(B22=0,0,C22+B22*(0.5+0.5*1/9)) | E22: =C22+B22 | F22: =F21+Inputs!G41
A23: =Inputs!B42 | B23: =Inputs!F42 | C23: =C22+B22 | D23: =IF(B23=0,0,C23+B23*(0.5+0.5*1/9)) | E23: =C23+B23 | F23: =F22+Inputs!G42
A24: =Inputs!B43 | B24: =Inputs!F43 | C24: =C23+B23 | D24: =IF(B24=0,0,C24+B24*(0.5+0.5*1/9)) | E24: =C24+B24 | F24: =F23+Inputs!G43
A25: =Inputs!B44 | B25: =Inputs!F44 | C25: =C24+B24 | D25: =IF(B25=0,0,C25+B25*(0.5+0.5*1/9)) | E25: =C25+B25 | F25: =F24+Inputs!G44
A28: Life planner (edit the blue cells: where each life rebirths)
A29: Life | B29: Qi realm reached | C29: Level | D29: Body stage reached | E29: Layer | F29: Qi × during life | G29: Body × during life | H29: Meditation h to reach (life 1 basis) | I29: Life length (days) | J29: Cumulative day | K29: Qi gain | L29: Body gain | M29: Qi Karma | N29: Body Karma | O29: Karma this rebirth | P29: Karma total | Q29: Qi × after | R29: Body × after | S29: Dao Marks if ascending now
A30: 1 | B30: GC | C30: 9 | D30: Silver Marrow | E30: 3 | F30: 1 | G30: 1 | H30: =INDEX(Qi_Pacing!$L$4:$L$93,MATCH(B30&" "&C30,Qi_Pacing!$A$4:$A$93,0)) | I30: =H30/F30/(Inputs!$B$10*Inputs!$B$11) | J30: =I30 | K30: =INDEX($C$5:$C$14,MATCH(B30,$A$5:$A$14,0))+INDEX($B$5:$B$14,MATCH(B30,$A$5:$A$14,0))*(0.5+0.5*C30/9) | L30: =INDEX($C$19:$C$25,MATCH(D30,$A$19:$A$25,0))+INDEX($B$19:$B$25,MATCH(D30,$A$19:$A$25,0))*(0.5+0.5*E30/9) | M30: =INDEX($F$5:$F$14,MATCH(B30,$A$5:$A$14,0)) | N30: =INDEX($F$19:$F$25,MATCH(D30,$A$19:$A$25,0)) | O30: =M30+N30 | P30: =O30 | Q30: =F30+K30 | R30: =G30+L30 | S30: =FLOOR(10*SQRT(Q30*R30),1)
A31: 2 | B31: NS | C31: 9 | D31: Jade Flesh | E31: 1 | F31: =F30+K30 | G31: =G30+L30 | H31: =INDEX(Qi_Pacing!$L$4:$L$93,MATCH(B31&" "&C31,Qi_Pacing!$A$4:$A$93,0)) | I31: =H31/F31/(Inputs!$B$10*Inputs!$B$11) | J31: =J30+I31 | K31: =INDEX($C$5:$C$14,MATCH(B31,$A$5:$A$14,0))+INDEX($B$5:$B$14,MATCH(B31,$A$5:$A$14,0))*(0.5+0.5*C31/9) | L31: =INDEX($C$19:$C$25,MATCH(D31,$A$19:$A$25,0))+INDEX($B$19:$B$25,MATCH(D31,$A$19:$A$25,0))*(0.5+0.5*E31/9) | M31: =INDEX($F$5:$F$14,MATCH(B31,$A$5:$A$14,0)) | N31: =INDEX($F$19:$F$25,MATCH(D31,$A$19:$A$25,0)) | O31: =M31+N31 | P31: =P30+O31 | Q31: =F31+K31 | R31: =G31+L31 | S31: =FLOOR(10*SQRT(Q31*R31),1)
A32: 3 | B32: NS | C32: 9 | D32: Jade Flesh | E32: 5 | F32: =F31+K31 | G32: =G31+L31 | H32: =INDEX(Qi_Pacing!$L$4:$L$93,MATCH(B32&" "&C32,Qi_Pacing!$A$4:$A$93,0)) | I32: =H32/F32/(Inputs!$B$10*Inputs!$B$11) | J32: =J31+I32 | K32: =INDEX($C$5:$C$14,MATCH(B32,$A$5:$A$14,0))+INDEX($B$5:$B$14,MATCH(B32,$A$5:$A$14,0))*(0.5+0.5*C32/9) | L32: =INDEX($C$19:$C$25,MATCH(D32,$A$19:$A$25,0))+INDEX($B$19:$B$25,MATCH(D32,$A$19:$A$25,0))*(0.5+0.5*E32/9) | M32: =INDEX($F$5:$F$14,MATCH(B32,$A$5:$A$14,0)) | N32: =INDEX($F$19:$F$25,MATCH(D32,$A$19:$A$25,0)) | O32: =M32+N32 | P32: =P31+O32 | Q32: =F32+K32 | R32: =G32+L32 | S32: =FLOOR(10*SQRT(Q32*R32),1)
A33: 4 | B33: SF | C33: 5 | D33: Jade Flesh | E33: 9 | F33: =F32+K32 | G33: =G32+L32 | H33: =INDEX(Qi_Pacing!$L$4:$L$93,MATCH(B33&" "&C33,Qi_Pacing!$A$4:$A$93,0)) | I33: =H33/F33/(Inputs!$B$10*Inputs!$B$11) | J33: =J32+I33 | K33: =INDEX($C$5:$C$14,MATCH(B33,$A$5:$A$14,0))+INDEX($B$5:$B$14,MATCH(B33,$A$5:$A$14,0))*(0.5+0.5*C33/9) | L33: =INDEX($C$19:$C$25,MATCH(D33,$A$19:$A$25,0))+INDEX($B$19:$B$25,MATCH(D33,$A$19:$A$25,0))*(0.5+0.5*E33/9) | M33: =INDEX($F$5:$F$14,MATCH(B33,$A$5:$A$14,0)) | N33: =INDEX($F$19:$F$25,MATCH(D33,$A$19:$A$25,0)) | O33: =M33+N33 | P33: =P32+O33 | Q33: =F33+K33 | R33: =G33+L33 | S33: =FLOOR(10*SQRT(Q33*R33),1)
A34: 5 | B34: VB | C34: 5 | D34: Golden Body | E34: 3 | F34: =F33+K33 | G34: =G33+L33 | H34: =INDEX(Qi_Pacing!$L$4:$L$93,MATCH(B34&" "&C34,Qi_Pacing!$A$4:$A$93,0)) | I34: =H34/F34/(Inputs!$B$10*Inputs!$B$11) | J34: =J33+I34 | K34: =INDEX($C$5:$C$14,MATCH(B34,$A$5:$A$14,0))+INDEX($B$5:$B$14,MATCH(B34,$A$5:$A$14,0))*(0.5+0.5*C34/9) | L34: =INDEX($C$19:$C$25,MATCH(D34,$A$19:$A$25,0))+INDEX($B$19:$B$25,MATCH(D34,$A$19:$A$25,0))*(0.5+0.5*E34/9) | M34: =INDEX($F$5:$F$14,MATCH(B34,$A$5:$A$14,0)) | N34: =INDEX($F$19:$F$25,MATCH(D34,$A$19:$A$25,0)) | O34: =M34+N34 | P34: =P33+O34 | Q34: =F34+K34 | R34: =G34+L34 | S34: =FLOOR(10*SQRT(Q34*R34),1)
A35: 6 | B35: MA | C35: 5 | D35: Golden Body | E35: 9 | F35: =F34+K34 | G35: =G34+L34 | H35: =INDEX(Qi_Pacing!$L$4:$L$93,MATCH(B35&" "&C35,Qi_Pacing!$A$4:$A$93,0)) | I35: =H35/F35/(Inputs!$B$10*Inputs!$B$11) | J35: =J34+I35 | K35: =INDEX($C$5:$C$14,MATCH(B35,$A$5:$A$14,0))+INDEX($B$5:$B$14,MATCH(B35,$A$5:$A$14,0))*(0.5+0.5*C35/9) | L35: =INDEX($C$19:$C$25,MATCH(D35,$A$19:$A$25,0))+INDEX($B$19:$B$25,MATCH(D35,$A$19:$A$25,0))*(0.5+0.5*E35/9) | M35: =INDEX($F$5:$F$14,MATCH(B35,$A$5:$A$14,0)) | N35: =INDEX($F$19:$F$25,MATCH(D35,$A$19:$A$25,0)) | O35: =M35+N35 | P35: =P34+O35 | Q35: =F35+K35 | R35: =G35+L35 | S35: =FLOOR(10*SQRT(Q35*R35),1)
A37: Life length = first-life meditation hours to reach that point ÷ the Qi multiplier during the life (approximation; body and gates not included).

Sheet Grounds_Economy
A1: Spirit Stone income vs Cultivation Ground upkeep
A3: Tier | B3: Realms | C3: Stones per hour (income)
A4: 1 | B4: MO–QS | C4: 200
A5: 2 | B5: FE | C5: 2000
A6: 3 | B6: GC | C6: 15000
A7: 4 | B7: NS | C7: 100000
A8: 5 | B8: SF | C8: =C7*Inputs!$B$18
A9: 6 | B9: VB | C9: =C8*Inputs!$B$18
A10: 7 | B10: MA | C10: =C9*Inputs!$B$18
A11: 8 | B11: GA 1–4 | C11: =C10*Inputs!$B$18
A12: 9 | B12: GA 5–9 | C12: =C11*Inputs!$B$18
A13: T1–T4 income from 03-Economy (Spirit Stone Flow); T5+ extrapolated ×7 per tier.
A15: Map # | B15: Ground | C15: Kind | D15: Multiplier | E15: Min realm | F15: Tier | G15: Upkeep/h (docs) | H15: Income/h at tier | I15: Upkeep share | J15: Recommended upkeep/h | K15: Check
A16: — | B16: Humble Hut | C16: Meditation | D16: 1 | E16: MO 1 | F16: 1 | G16: 0 | H16: =INDEX($C$4:$C$12,F16) | I16: =IFERROR(G16/H16,0) | J16: =IF(G16>0,ROUND(H16*Inputs!$B$19,-2),0) | K16: =IF(G16=0,"—",IF(AND(I16>=0.1,I16<=0.15),"OK","Retune"))
A17: — | B17: Village Courtyard | C17: Training | D17: 1 | E17: QC 1 | F17: 1 | G17: 0 | H17: =INDEX($C$4:$C$12,F17) | I17: =IFERROR(G17/H17,0) | J17: =IF(G17>0,ROUND(H17*Inputs!$B$19,-2),0) | K17: =IF(G17=0,"—",IF(AND(I17>=0.1,I17<=0.15),"OK","Retune"))
A18: 1 | B18: Bamboo Grove Hermitage | C18: Meditation | D18: 1.1 | E18: MO 5 | F18: 1 | G18: 0 | H18: =INDEX($C$4:$C$12,F18) | I18: =IFERROR(G18/H18,0) | J18: =IF(G18>0,ROUND(H18*Inputs!$B$19,-2),0) | K18: =IF(G18=0,"—",IF(AND(I18>=0.1,I18<=0.15),"OK","Retune"))
A19: 2 | B19: Pass Fort Drill Yard | C19: Training | D19: 1.1 | E19: QC 7 | F19: 1 | G19: 0 | H19: =INDEX($C$4:$C$12,F19) | I19: =IFERROR(G19/H19,0) | J19: =IF(G19>0,ROUND(H19*Inputs!$B$19,-2),0) | K19: =IF(G19=0,"—",IF(AND(I19>=0.1,I19<=0.15),"OK","Retune"))
A20: 3 | B20: Moonlit Lake Pavilion | C20: Meditation | D20: 1.2 | E20: FE 1 | F20: 2 | G20: 0 | H20: =INDEX($C$4:$C$12,F20) | I20: =IFERROR(G20/H20,0) | J20: =IF(G20>0,ROUND(H20*Inputs!$B$19,-2),0) | K20: =IF(G20=0,"—",IF(AND(I20>=0.1,I20<=0.15),"OK","Retune"))
A21: 4 | B21: Ember Hot Springs | C21: Training | D21: 1.25 | E21: FE 4 | F21: 2 | G21: 0 | H21: =INDEX($C$4:$C$12,F21) | I21: =IFERROR(G21/H21,0) | J21: =IF(G21>0,ROUND(H21*Inputs!$B$19,-2),0) | K21: =IF(G21=0,"—",IF(AND(I21>=0.1,I21<=0.15),"OK","Retune"))
A22: 5 | B22: Ruined Meditation Hall | C22: Meditation | D22: 1.3 | E22: FE 8 | F22: 2 | G22: 0 | H22: =INDEX($C$4:$C$12,F22) | I22: =IFERROR(G22/H22,0) | J22: =IF(G22>0,ROUND(H22*Inputs!$B$19,-2),0) | K22: =IF(G22=0,"—",IF(AND(I22>=0.1,I22<=0.15),"OK","Retune"))
A23: 6 | B23: Thunderstruck Summit | C23: Training | D23: 1.35 | E23: GC 2 | F23: 3 | G23: 0 | H23: =INDEX($C$4:$C$12,F23) | I23: =IFERROR(G23/H23,0) | J23: =IF(G23>0,ROUND(H23*Inputs!$B$19,-2),0) | K23: =IF(G23=0,"—",IF(AND(I23>=0.1,I23<=0.15),"OK","Retune"))
A24: 7 | B24: Venom-Steeped Pools | C24: Training | D24: 1.45 | E24: GC 5 | F24: 3 | G24: 0 | H24: =INDEX($C$4:$C$12,F24) | I24: =IFERROR(G24/H24,0) | J24: =IF(G24>0,ROUND(H24*Inputs!$B$19,-2),0) | K24: =IF(G24=0,"—",IF(AND(I24>=0.1,I24<=0.15),"OK","Retune"))
A25: 8 | B25: Glacial Cave of Stillness | C25: Meditation | D25: 1.5 | E25: GC 8 | F25: 3 | G25: 0 | H25: =INDEX($C$4:$C$12,F25) | I25: =IFERROR(G25/H25,0) | J25: =IF(G25>0,ROUND(H25*Inputs!$B$19,-2),0) | K25: =IF(G25=0,"—",IF(AND(I25>=0.1,I25<=0.15),"OK","Retune"))
A26: 9 | B26: Sunscorch Dunes | C26: Training | D26: 1.6 | E26: NS 1 | F26: 4 | G26: 0 | H26: =INDEX($C$4:$C$12,F26) | I26: =IFERROR(G26/H26,0) | J26: =IF(G26>0,ROUND(H26*Inputs!$B$19,-2),0) | K26: =IF(G26=0,"—",IF(AND(I26>=0.1,I26<=0.15),"OK","Retune"))
A27: 10 | B27: Yin Spirit Altar | C27: Meditation | D27: 1.65 | E27: NS 4 | F27: 4 | G27: 0 | H27: =INDEX($C$4:$C$12,F27) | I27: =IFERROR(G27/H27,0) | J27: =IF(G27>0,ROUND(H27*Inputs!$B$19,-2),0) | K27: =IF(G27=0,"—",IF(AND(I27>=0.1,I27<=0.15),"OK","Retune"))
... A43: 26 | B43: Summit of Heaven | C43: Both | D43: 4.5 | E43: GA 8 | F43: 9 | G43: 250000000 | H43: =INDEX($C$4:$C$12,F43) | I43: =IFERROR(G43/H43,0) | J43: =IF(G43>0,ROUND(H43*Inputs!$B$19,-2),0) | K43: =IF(G43=0,"—",IF(AND(I43>=0.1,I43<=0.15),"OK","Retune"))
A45: Upkeep (docs) is from content/15-Cultivation-Grounds, set to 10% / 12% / 14–15% of tier income for the 1st/2nd/3rd ground of each tier. Tier is mapped from the ground's minimum realm.

Sheet Checks
A1: Checks
A3: 1. Qi realm pacing vs registry targets (first life)
